[2021-01-21 01:52:00,213 hoshino] CRITICAL: Self: 1142643359, Message -275995813 from 123337671: kkp
[2021-01-21 01:52:00,466 hoshino] ERROR: 禁言失败 retcode=100
[2021-01-21 01:52:07,074 hoshino] CRITICAL: Self: 1142643359, Message 1171529455 from 123337671: kkp
[2021-01-21 01:52:07,327 hoshino] ERROR: 禁言失败 retcode=100
[2021-01-21 01:52:11,278 hoshino] CRITICAL: Self: 1142643359, Message 852700793 from 123337671: kkp
[2021-01-21 01:52:11,499 hoshino] ERROR: 禁言失败 retcode=100
[2021-01-21 01:52:15,308 hoshino] CRITICAL: Self: 1142643359, Message -1411743805 from 123337671: kkp
[2021-01-21 01:52:15,571 hoshino] ERROR: 禁言失败 retcode=100
[2021-01-21 01:52:17,398 hoshino] CRITICAL: Self: 1142643359, Message -589476011 from 123337671: kkp
[2021-01-21 01:52:17,680 hoshino] ERROR: 禁言失败 retcode=100
[2021-01-21 01:56:56,835 hoshino] CRITICAL: Self: 1142643359, Message -1397244966 from 123337671: kkp
[2021-01-21 01:56:57,089 hoshino] ERROR: 禁言失败 retcode=100
[2021-01-21 01:57:27,123 hoshino] CRITICAL: Self: 1142643359, Message 1007199819 from 123337671: kkp
[2021-01-21 01:57:27,324 hoshino] ERROR: 禁言失败 retcode=100
[2021-01-21 01:57:47,175 hoshino] CRITICAL: Self: 1142643359, Message 1557082030 from 123337671: kkp
[2021-01-21 01:57:47,448 hoshino] ERROR: 禁言失败 retcode=100
[2021-01-21 02:38:52,031 chara] ERROR: Failed to download https://redive.estertion.win/icon/unit/114561.webp. HTTP 404
[2021-01-21 10:38:33,100 hoshino] CRITICAL: Self: 1142643359, Message 1808781967 from 123337671@[群:526850985]:  kkp
[2021-01-21 11:10:39,665 setu] ERROR: <class 'FileNotFoundError'> occured when setu handling message -1208495839.
[2021-01-21 11:10:39,666 setu] ERROR: [Errno 2] No such file or directory: './res/img/setu'
Traceback (most recent call last):
  File "/root/HoshinoBot/hoshino/msghandler.py", line 28, in handle_message
    await sf.func(bot, event)
  File "/root/HoshinoBot/hoshino/modules/setu/setu.py", line 45, in setu
    pic = get_setu()
  File "/root/HoshinoBot/hoshino/modules/setu/setu.py", line 28, in get_setu
    return setu_gener.__next__()
  File "/root/HoshinoBot/hoshino/modules/setu/setu.py", line 19, in setu_gener
    filelist = os.listdir(setu_folder)
FileNotFoundError: [Errno 2] No such file or directory: './res/img/setu'
[2021-01-21 11:40:55,397 hoshino] ERROR: 缺少图片资源：./res/img/priconne/gadget/thumb-up-i.png
[2021-01-21 11:40:55,398 pcr-arena] ERROR: [Errno 2] No such file or directory: './res/img/priconne/gadget/thumb-up-i.png'
Traceback (most recent call last):
  File "/root/HoshinoBot/hoshino/modules/priconne/arena/__init__.py", line 31, in <module>
    thumb_up_i = R.img('priconne/gadget/thumb-up-i.png').open().resize((16, 16), Image.LANCZOS)
  File "/root/HoshinoBot/hoshino/R.py", line 50, in open
    return Image.open(self.path)
  File "/usr/local/lib/python3.8/site-packages/PIL/Image.py", line 2904, in open
    fp = builtins.open(filename, "rb")
FileNotFoundError: [Errno 2] No such file or directory: './res/img/priconne/gadget/thumb-up-i.png'
[2021-01-21 11:54:11,473 chat] ERROR: <class 'aiocqhttp.exceptions.ActionFailed'> occured when chat_waifu handling message 1361952398.
[2021-01-21 11:54:11,474 chat] ERROR: <ActionFailed, retcode=100>
Traceback (most recent call last):
  File "/root/HoshinoBot/hoshino/msghandler.py", line 28, in handle_message
    await sf.func(bot, event)
  File "/root/HoshinoBot/hoshino/service.py", line 218, in wrapper
    return await func(bot, event)
  File "/root/HoshinoBot/hoshino/modules/groupmaster/chat.py", line 24, in chat_waifu
    await bot.send(ev, R.img('laopo.jpg').cqcode)
  File "/usr/local/lib/python3.8/site-packages/aiocqhttp/__init__.py", line 256, in send
    return await self.send_msg(**params)
  File "/usr/local/lib/python3.8/site-packages/aiocqhttp/__init__.py", line 223, in call_action
    return await self._api.call_action(action=action, **params)
  File "/usr/local/lib/python3.8/site-packages/aiocqhttp/api_impl.py", line 186, in call_action
    result = await self._wsr_api.call_action(action, **params)
  File "/usr/local/lib/python3.8/site-packages/aiocqhttp/api_impl.py", line 161, in call_action
    return _handle_api_result(
  File "/usr/local/lib/python3.8/site-packages/aiocqhttp/api_impl.py", line 51, in _handle_api_result
    raise ActionFailed(retcode=result.get('retcode'))
aiocqhttp.exceptions.ActionFailed: <ActionFailed, retcode=100>
[2021-01-21 11:54:27,278 chat] ERROR: <class 'aiocqhttp.exceptions.ActionFailed'> occured when chat_waifu handling message -840048259.
[2021-01-21 11:54:27,279 chat] ERROR: <ActionFailed, retcode=100>
Traceback (most recent call last):
  File "/root/HoshinoBot/hoshino/msghandler.py", line 28, in handle_message
    await sf.func(bot, event)
  File "/root/HoshinoBot/hoshino/service.py", line 218, in wrapper
    return await func(bot, event)
  File "/root/HoshinoBot/hoshino/modules/groupmaster/chat.py", line 24, in chat_waifu
    await bot.send(ev, R.img('laopo.jpg').cqcode)
  File "/usr/local/lib/python3.8/site-packages/aiocqhttp/__init__.py", line 256, in send
    return await self.send_msg(**params)
  File "/usr/local/lib/python3.8/site-packages/aiocqhttp/__init__.py", line 223, in call_action
    return await self._api.call_action(action=action, **params)
  File "/usr/local/lib/python3.8/site-packages/aiocqhttp/api_impl.py", line 186, in call_action
    result = await self._wsr_api.call_action(action, **params)
  File "/usr/local/lib/python3.8/site-packages/aiocqhttp/api_impl.py", line 161, in call_action
    return _handle_api_result(
  File "/usr/local/lib/python3.8/site-packages/aiocqhttp/api_impl.py", line 51, in _handle_api_result
    raise ActionFailed(retcode=result.get('retcode'))
aiocqhttp.exceptions.ActionFailed: <ActionFailed, retcode=100>
[2021-01-21 12:01:09,684 hoshino] ERROR: 缺少图片资源：./res/img/priconne/gadget/thumb-up-i.png
[2021-01-21 12:01:09,684 pcr-arena] ERROR: [Errno 2] No such file or directory: './res/img/priconne/gadget/thumb-up-i.png'
Traceback (most recent call last):
  File "/root/HoshinoBot/hoshino/modules/priconne/arena/__init__.py", line 31, in <module>
    thumb_up_i = R.img('priconne/gadget/thumb-up-i.png').open().resize((16, 16), Image.LANCZOS)
  File "/root/HoshinoBot/hoshino/R.py", line 50, in open
    return Image.open(self.path)
  File "/usr/local/lib/python3.8/site-packages/PIL/Image.py", line 2904, in open
    fp = builtins.open(filename, "rb")
FileNotFoundError: [Errno 2] No such file or directory: './res/img/priconne/gadget/thumb-up-i.png'
[2021-01-21 12:28:47,253 chat] ERROR: <class 'aiocqhttp.exceptions.ActionFailed'> occured when chat_waifu handling message -899179191.
[2021-01-21 12:28:47,254 chat] ERROR: <ActionFailed, retcode=100>
Traceback (most recent call last):
  File "/root/HoshinoBot/hoshino/msghandler.py", line 28, in handle_message
    await sf.func(bot, event)
  File "/root/HoshinoBot/hoshino/service.py", line 218, in wrapper
    return await func(bot, event)
  File "/root/HoshinoBot/hoshino/modules/groupmaster/chat.py", line 24, in chat_waifu
    await bot.send(ev, R.img('laopo.jpg').cqcode)
  File "/usr/local/lib/python3.8/site-packages/aiocqhttp/__init__.py", line 256, in send
    return await self.send_msg(**params)
  File "/usr/local/lib/python3.8/site-packages/aiocqhttp/__init__.py", line 223, in call_action
    return await self._api.call_action(action=action, **params)
  File "/usr/local/lib/python3.8/site-packages/aiocqhttp/api_impl.py", line 186, in call_action
    result = await self._wsr_api.call_action(action, **params)
  File "/usr/local/lib/python3.8/site-packages/aiocqhttp/api_impl.py", line 161, in call_action
    return _handle_api_result(
  File "/usr/local/lib/python3.8/site-packages/aiocqhttp/api_impl.py", line 51, in _handle_api_result
    raise ActionFailed(retcode=result.get('retcode'))
aiocqhttp.exceptions.ActionFailed: <ActionFailed, retcode=100>
[2021-01-21 12:29:57,487 hoshino] CRITICAL: Self: 1142643359, Message 337439898 from 123337671@[群:1018872051]:  nmsl
[2021-01-21 12:30:04,605 hoshino] CRITICAL: Self: 1142643359, Message 1434907247 from 123337671@[群:1018872051]:  nmsl
[2021-01-21 12:32:16,416 hoshino] CRITICAL: Self: 1142643359, Message 636225248 from 1013925386@[群:1018872051]:  cnm
[2021-01-21 12:34:56,060 hoshino] ERROR: 缺少图片资源：./res/img/priconne/gadget/thumb-up-i.png
[2021-01-21 12:34:56,060 pcr-arena] ERROR: [Errno 2] No such file or directory: './res/img/priconne/gadget/thumb-up-i.png'
Traceback (most recent call last):
  File "/root/HoshinoBot/hoshino/modules/priconne/arena/__init__.py", line 31, in <module>
    thumb_up_i = R.img('priconne/gadget/thumb-up-i.png').open().resize((16, 16), Image.LANCZOS)
  File "/root/HoshinoBot/hoshino/R.py", line 50, in open
    return Image.open(self.path)
  File "/usr/local/lib/python3.8/site-packages/PIL/Image.py", line 2904, in open
    fp = builtins.open(filename, "rb")
FileNotFoundError: [Errno 2] No such file or directory: './res/img/priconne/gadget/thumb-up-i.png'
[2021-01-21 12:35:50,629 hoshino] CRITICAL: Self: 1142643359, Message 744114891 from 123337671@[群:1018872051]:  kkp
[2021-01-21 12:36:13,439 hoshino] CRITICAL: Self: 1142643359, Message 2033841247 from 123337671: kkp
[2021-01-21 12:36:13,455 hoshino] ERROR: 禁言失败 retcode=100
[2021-01-21 12:37:38,806 hoshino] CRITICAL: Self: 1142643359, Message -1026262211 from 123337671@[群:526850985]:  kkp
[2021-01-21 12:37:47,316 hoshino] CRITICAL: Self: 1142643359, Message 1000010680 from 123337671@[群:1018872051]:  kkp
[2021-01-21 13:01:19,929 hoshino] ERROR: 缺少图片资源：./res/img/priconne/gadget/thumb-up-i.png
[2021-01-21 13:01:19,929 pcr-arena] ERROR: [Errno 2] No such file or directory: './res/img/priconne/gadget/thumb-up-i.png'
Traceback (most recent call last):
  File "/root/HoshinoBot/hoshino/modules/priconne/arena/__init__.py", line 31, in <module>
    thumb_up_i = R.img('priconne/gadget/thumb-up-i.png').open().resize((16, 16), Image.LANCZOS)
  File "/root/HoshinoBot/hoshino/R.py", line 50, in open
    return Image.open(self.path)
  File "/usr/local/lib/python3.8/site-packages/PIL/Image.py", line 2904, in open
    fp = builtins.open(filename, "rb")
FileNotFoundError: [Errno 2] No such file or directory: './res/img/priconne/gadget/thumb-up-i.png'
[2021-01-21 15:48:53,393 hoshino] CRITICAL: Self: 1142643359, Message -477500371 from 123337671@[群:526850985]:  kkp
[2021-01-21 15:49:08,918 hoshino] CRITICAL: Self: 1142643359, Message 1861831980 from 123337671: kkp
[2021-01-21 15:49:09,207 hoshino] ERROR: 禁言失败 retcode=100
[2021-01-21 15:49:11,538 hoshino] CRITICAL: Self: 1142643359, Message 436108730 from 123337671: kkp
[2021-01-21 15:49:11,789 hoshino] ERROR: 禁言失败 retcode=100
[2021-01-21 15:49:14,033 hoshino] CRITICAL: Self: 1142643359, Message -2131284992 from 123337671: kkp
[2021-01-21 15:49:14,250 hoshino] ERROR: 禁言失败 retcode=100
[2021-01-21 15:49:16,226 hoshino] CRITICAL: Self: 1142643359, Message -135258986 from 123337671: kkp
[2021-01-21 15:49:16,588 hoshino] ERROR: 禁言失败 retcode=100
[2021-01-21 15:57:39,738 hoshino] ERROR: 缺少图片资源：./res/img/priconne/gadget/thumb-up-i.png
[2021-01-21 15:57:39,739 pcr-arena] ERROR: [Errno 2] No such file or directory: './res/img/priconne/gadget/thumb-up-i.png'
Traceback (most recent call last):
  File "/root/HoshinoBot/hoshino/modules/priconne/arena/__init__.py", line 31, in <module>
    thumb_up_i = R.img('priconne/gadget/thumb-up-i.png').open().resize((16, 16), Image.LANCZOS)
  File "/root/HoshinoBot/hoshino/R.py", line 50, in open
    return Image.open(self.path)
  File "/usr/local/lib/python3.8/site-packages/PIL/Image.py", line 2904, in open
    fp = builtins.open(filename, "rb")
FileNotFoundError: [Errno 2] No such file or directory: './res/img/priconne/gadget/thumb-up-i.png'
[2021-01-21 16:43:15,728 anti-holo] ERROR: <class 'aiocqhttp.exceptions.ActionFailed'> occured when anti_holo handling message 1770385670.
[2021-01-21 16:43:15,729 anti-holo] ERROR: <ActionFailed, retcode=100>
Traceback (most recent call last):
  File "/root/HoshinoBot/hoshino/msghandler.py", line 28, in handle_message
    await sf.func(bot, event)
  File "/root/HoshinoBot/hoshino/modules/groupmaster/anti_holo.py", line 110, in anti_holo
    await bot.send(ev, HAHAHA_VTB_TIANGOU.cqcode)
  File "/usr/local/lib/python3.8/site-packages/aiocqhttp/__init__.py", line 256, in send
    return await self.send_msg(**params)
  File "/usr/local/lib/python3.8/site-packages/aiocqhttp/__init__.py", line 223, in call_action
    return await self._api.call_action(action=action, **params)
  File "/usr/local/lib/python3.8/site-packages/aiocqhttp/api_impl.py", line 186, in call_action
    result = await self._wsr_api.call_action(action, **params)
  File "/usr/local/lib/python3.8/site-packages/aiocqhttp/api_impl.py", line 161, in call_action
    return _handle_api_result(
  File "/usr/local/lib/python3.8/site-packages/aiocqhttp/api_impl.py", line 51, in _handle_api_result
    raise ActionFailed(retcode=result.get('retcode'))
aiocqhttp.exceptions.ActionFailed: <ActionFailed, retcode=100>
[2021-01-21 17:36:32,929 chara] ERROR: Failed to download https://redive.estertion.win/icon/unit/113561.webp. HTTP 404
[2021-01-21 19:26:04,397 pcr-arena] ERROR: Arena query failed.
Response={'code': 103, 'message': '103', 'version': '20210118'}
Payload={'_sign': 'a', 'def': [101201, 108201, 108101, 102901, 105201], 'nonce': 'a', 'page': 1, 'sort': 1, 'ts': 1611228363, 'region': 1}
[2021-01-21 19:27:03,481 pcr-arena] ERROR: Arena query failed.
Response={'code': 103, 'message': '103', 'version': '20210118'}
Payload={'_sign': 'a', 'def': [101201, 108201, 108101, 102901, 105201], 'nonce': 'a', 'page': 1, 'sort': 1, 'ts': 1611228422, 'region': 1}
[2021-01-21 19:27:13,912 pcr-arena] ERROR: Arena query failed.
Response={'code': 103, 'message': '103', 'version': '20210118'}
Payload={'_sign': 'a', 'def': [101201, 108201, 108101, 102901, 100701], 'nonce': 'a', 'page': 1, 'sort': 1, 'ts': 1611228433, 'region': 1}
[2021-01-21 19:41:43,793 pcr-arena] ERROR: Arena query failed.
Response={'code': 103, 'message': '103', 'version': '20210118'}
Payload={'_sign': 'a', 'def': [101201, 108201, 108101, 102901, 105201], 'nonce': 'a', 'page': 1, 'sort': 1, 'ts': 1611229303, 'region': 1}
[2021-01-21 20:13:54,951 hoshino] ERROR: 缺少图片资源：./res/img/priconne/gadget/thumb-up-i.png
[2021-01-21 20:13:54,951 pcr-arena] ERROR: [Errno 2] No such file or directory: './res/img/priconne/gadget/thumb-up-i.png'
Traceback (most recent call last):
  File "/root/HoshinoBot/hoshino/modules/priconne/arena/__init__.py", line 31, in <module>
    thumb_up_i = R.img('priconne/gadget/thumb-up-i.png').open().resize((16, 16), Image.LANCZOS)
  File "/root/HoshinoBot/hoshino/R.py", line 50, in open
    return Image.open(self.path)
  File "/usr/local/lib/python3.8/site-packages/PIL/Image.py", line 2904, in open
    fp = builtins.open(filename, "rb")
FileNotFoundError: [Errno 2] No such file or directory: './res/img/priconne/gadget/thumb-up-i.png'
[2021-01-21 20:35:17,796 hoshino] ERROR: 缺少图片资源：./res/img/priconne/gadget/thumb-up-i.png
[2021-01-21 20:35:17,796 pcr-arena] ERROR: [Errno 2] No such file or directory: './res/img/priconne/gadget/thumb-up-i.png'
Traceback (most recent call last):
  File "/root/HoshinoBot/hoshino/modules/priconne/arena/__init__.py", line 31, in <module>
    thumb_up_i = R.img('priconne/gadget/thumb-up-i.png').open().resize((16, 16), Image.LANCZOS)
  File "/root/HoshinoBot/hoshino/R.py", line 50, in open
    return Image.open(self.path)
  File "/usr/local/lib/python3.8/site-packages/PIL/Image.py", line 2904, in open
    fp = builtins.open(filename, "rb")
FileNotFoundError: [Errno 2] No such file or directory: './res/img/priconne/gadget/thumb-up-i.png'
[2021-01-21 20:35:18,074 nonebot] ERROR: Failed to import "hoshino.modules.rua.data_source", error: No module named 'hoshino.modules._res'
[2021-01-21 20:35:18,075 nonebot] ERROR: No module named 'hoshino.modules._res'
Traceback (most recent call last):
  File "/usr/local/lib/python3.8/site-packages/nonebot/plugin.py", line 274, in load_plugin
    module = importlib.import_module(module_path)
  File "/usr/local/lib/python3.8/importlib/__init__.py", line 127, in import_module
    return _bootstrap._gcd_import(name[level:], package, level)
  File "<frozen importlib._bootstrap>", line 1014, in _gcd_import
  File "<frozen importlib._bootstrap>", line 991, in _find_and_load
  File "<frozen importlib._bootstrap>", line 961, in _find_and_load_unlocked
  File "<frozen importlib._bootstrap>", line 219, in _call_with_frames_removed
  File "<frozen importlib._bootstrap>", line 1014, in _gcd_import
  File "<frozen importlib._bootstrap>", line 991, in _find_and_load
  File "<frozen importlib._bootstrap>", line 975, in _find_and_load_unlocked
  File "<frozen importlib._bootstrap>", line 671, in _load_unlocked
  File "<frozen importlib._bootstrap_external>", line 783, in exec_module
  File "<frozen importlib._bootstrap>", line 219, in _call_with_frames_removed
  File "/root/HoshinoBot/hoshino/modules/rua/__init__.py", line 10, in <module>
    from .._res import Res as R
ModuleNotFoundError: No module named 'hoshino.modules._res'
[2021-01-21 20:38:49,858 nonebot] ERROR: Failed to import "hoshino.modules.rua.data_source", error: No module named 'hoshino.modules._res'
[2021-01-21 20:38:49,858 nonebot] ERROR: No module named 'hoshino.modules._res'
Traceback (most recent call last):
  File "/usr/local/lib/python3.8/site-packages/nonebot/plugin.py", line 274, in load_plugin
    module = importlib.import_module(module_path)
  File "/usr/local/lib/python3.8/importlib/__init__.py", line 127, in import_module
    return _bootstrap._gcd_import(name[level:], package, level)
  File "<frozen importlib._bootstrap>", line 1014, in _gcd_import
  File "<frozen importlib._bootstrap>", line 991, in _find_and_load
  File "<frozen importlib._bootstrap>", line 961, in _find_and_load_unlocked
  File "<frozen importlib._bootstrap>", line 219, in _call_with_frames_removed
  File "<frozen importlib._bootstrap>", line 1014, in _gcd_import
  File "<frozen importlib._bootstrap>", line 991, in _find_and_load
  File "<frozen importlib._bootstrap>", line 975, in _find_and_load_unlocked
  File "<frozen importlib._bootstrap>", line 671, in _load_unlocked
  File "<frozen importlib._bootstrap_external>", line 783, in exec_module
  File "<frozen importlib._bootstrap>", line 219, in _call_with_frames_removed
  File "/root/HoshinoBot/hoshino/modules/rua/__init__.py", line 10, in <module>
    from .._res import Res as R
ModuleNotFoundError: No module named 'hoshino.modules._res'
[2021-01-21 20:38:50,252 hoshino] ERROR: 缺少图片资源：./res/img/priconne/gadget/thumb-up-i.png
[2021-01-21 20:38:50,253 pcr-arena] ERROR: [Errno 2] No such file or directory: './res/img/priconne/gadget/thumb-up-i.png'
Traceback (most recent call last):
  File "/root/HoshinoBot/hoshino/modules/priconne/arena/__init__.py", line 31, in <module>
    thumb_up_i = R.img('priconne/gadget/thumb-up-i.png').open().resize((16, 16), Image.LANCZOS)
  File "/root/HoshinoBot/hoshino/R.py", line 50, in open
    return Image.open(self.path)
  File "/usr/local/lib/python3.8/site-packages/PIL/Image.py", line 2904, in open
    fp = builtins.open(filename, "rb")
FileNotFoundError: [Errno 2] No such file or directory: './res/img/priconne/gadget/thumb-up-i.png'
[2021-01-21 20:41:28,813 nonebot] ERROR: Failed to import "hoshino.modules.rua.data_source", error: No module named 'hoshino.modules._res'
[2021-01-21 20:41:28,814 nonebot] ERROR: No module named 'hoshino.modules._res'
Traceback (most recent call last):
  File "/usr/local/lib/python3.8/site-packages/nonebot/plugin.py", line 274, in load_plugin
    module = importlib.import_module(module_path)
  File "/usr/local/lib/python3.8/importlib/__init__.py", line 127, in import_module
    return _bootstrap._gcd_import(name[level:], package, level)
  File "<frozen importlib._bootstrap>", line 1014, in _gcd_import
  File "<frozen importlib._bootstrap>", line 991, in _find_and_load
  File "<frozen importlib._bootstrap>", line 961, in _find_and_load_unlocked
  File "<frozen importlib._bootstrap>", line 219, in _call_with_frames_removed
  File "<frozen importlib._bootstrap>", line 1014, in _gcd_import
  File "<frozen importlib._bootstrap>", line 991, in _find_and_load
  File "<frozen importlib._bootstrap>", line 975, in _find_and_load_unlocked
  File "<frozen importlib._bootstrap>", line 671, in _load_unlocked
  File "<frozen importlib._bootstrap_external>", line 783, in exec_module
  File "<frozen importlib._bootstrap>", line 219, in _call_with_frames_removed
  File "/root/HoshinoBot/hoshino/modules/rua/__init__.py", line 9, in <module>
    from .._res import Res as R
ModuleNotFoundError: No module named 'hoshino.modules._res'
[2021-01-21 20:41:28,979 hoshino] ERROR: 缺少图片资源：./res/img/priconne/gadget/thumb-up-i.png
[2021-01-21 20:41:28,980 pcr-arena] ERROR: [Errno 2] No such file or directory: './res/img/priconne/gadget/thumb-up-i.png'
Traceback (most recent call last):
  File "/root/HoshinoBot/hoshino/modules/priconne/arena/__init__.py", line 31, in <module>
    thumb_up_i = R.img('priconne/gadget/thumb-up-i.png').open().resize((16, 16), Image.LANCZOS)
  File "/root/HoshinoBot/hoshino/R.py", line 50, in open
    return Image.open(self.path)
  File "/usr/local/lib/python3.8/site-packages/PIL/Image.py", line 2904, in open
    fp = builtins.open(filename, "rb")
FileNotFoundError: [Errno 2] No such file or directory: './res/img/priconne/gadget/thumb-up-i.png'
[2021-01-21 20:44:41,387 nonebot] ERROR: Failed to import "hoshino.modules.rua.data_source", error: No module named 'filetype'
[2021-01-21 20:44:41,387 nonebot] ERROR: No module named 'filetype'
Traceback (most recent call last):
  File "/usr/local/lib/python3.8/site-packages/nonebot/plugin.py", line 274, in load_plugin
    module = importlib.import_module(module_path)
  File "/usr/local/lib/python3.8/importlib/__init__.py", line 127, in import_module
    return _bootstrap._gcd_import(name[level:], package, level)
  File "<frozen importlib._bootstrap>", line 1014, in _gcd_import
  File "<frozen importlib._bootstrap>", line 991, in _find_and_load
  File "<frozen importlib._bootstrap>", line 961, in _find_and_load_unlocked
  File "<frozen importlib._bootstrap>", line 219, in _call_with_frames_removed
  File "<frozen importlib._bootstrap>", line 1014, in _gcd_import
  File "<frozen importlib._bootstrap>", line 991, in _find_and_load
  File "<frozen importlib._bootstrap>", line 975, in _find_and_load_unlocked
  File "<frozen importlib._bootstrap>", line 671, in _load_unlocked
  File "<frozen importlib._bootstrap_external>", line 783, in exec_module
  File "<frozen importlib._bootstrap>", line 219, in _call_with_frames_removed
  File "/root/HoshinoBot/hoshino/modules/rua/__init__.py", line 10, in <module>
    from .._res import Res as R
  File "/root/HoshinoBot/hoshino/modules/_res.py", line 10, in <module>
    from filetype.filetype import guess_mime
ModuleNotFoundError: No module named 'filetype'
[2021-01-21 20:44:41,556 hoshino] ERROR: 缺少图片资源：./res/img/priconne/gadget/thumb-up-i.png
[2021-01-21 20:44:41,556 pcr-arena] ERROR: [Errno 2] No such file or directory: './res/img/priconne/gadget/thumb-up-i.png'
Traceback (most recent call last):
  File "/root/HoshinoBot/hoshino/modules/priconne/arena/__init__.py", line 31, in <module>
    thumb_up_i = R.img('priconne/gadget/thumb-up-i.png').open().resize((16, 16), Image.LANCZOS)
  File "/root/HoshinoBot/hoshino/R.py", line 50, in open
    return Image.open(self.path)
  File "/usr/local/lib/python3.8/site-packages/PIL/Image.py", line 2904, in open
    fp = builtins.open(filename, "rb")
FileNotFoundError: [Errno 2] No such file or directory: './res/img/priconne/gadget/thumb-up-i.png'
[2021-01-21 20:48:00,922 hoshino] ERROR: 缺少图片资源：./res/img/priconne/gadget/thumb-up-i.png
[2021-01-21 20:48:00,923 pcr-arena] ERROR: [Errno 2] No such file or directory: './res/img/priconne/gadget/thumb-up-i.png'
Traceback (most recent call last):
  File "/root/HoshinoBot/hoshino/modules/priconne/arena/__init__.py", line 31, in <module>
    thumb_up_i = R.img('priconne/gadget/thumb-up-i.png').open().resize((16, 16), Image.LANCZOS)
  File "/root/HoshinoBot/hoshino/R.py", line 50, in open
    return Image.open(self.path)
  File "/usr/local/lib/python3.8/site-packages/PIL/Image.py", line 2904, in open
    fp = builtins.open(filename, "rb")
FileNotFoundError: [Errno 2] No such file or directory: './res/img/priconne/gadget/thumb-up-i.png'
[2021-01-21 20:48:01,322 nonebot] ERROR: Failed to import "hoshino.modules.rua.data_source", error: No module named 'hoshino.modules._util'
[2021-01-21 20:48:01,322 nonebot] ERROR: No module named 'hoshino.modules._util'
Traceback (most recent call last):
  File "/usr/local/lib/python3.8/site-packages/nonebot/plugin.py", line 274, in load_plugin
    module = importlib.import_module(module_path)
  File "/usr/local/lib/python3.8/importlib/__init__.py", line 127, in import_module
    return _bootstrap._gcd_import(name[level:], package, level)
  File "<frozen importlib._bootstrap>", line 1014, in _gcd_import
  File "<frozen importlib._bootstrap>", line 991, in _find_and_load
  File "<frozen importlib._bootstrap>", line 961, in _find_and_load_unlocked
  File "<frozen importlib._bootstrap>", line 219, in _call_with_frames_removed
  File "<frozen importlib._bootstrap>", line 1014, in _gcd_import
  File "<frozen importlib._bootstrap>", line 991, in _find_and_load
  File "<frozen importlib._bootstrap>", line 975, in _find_and_load_unlocked
  File "<frozen importlib._bootstrap>", line 671, in _load_unlocked
  File "<frozen importlib._bootstrap_external>", line 783, in exec_module
  File "<frozen importlib._bootstrap>", line 219, in _call_with_frames_removed
  File "/root/HoshinoBot/hoshino/modules/rua/__init__.py", line 10, in <module>
    from .._res import Res as R
  File "/root/HoshinoBot/hoshino/modules/_res.py", line 15, in <module>
    from ._util import download_async, get_md5, get_random_file, logger, bot
ModuleNotFoundError: No module named 'hoshino.modules._util'
[2021-01-21 20:48:32,675 hoshino] ERROR: 缺少图片资源：./res/img/priconne/gadget/thumb-up-i.png
[2021-01-21 20:48:32,675 pcr-arena] ERROR: [Errno 2] No such file or directory: './res/img/priconne/gadget/thumb-up-i.png'
Traceback (most recent call last):
  File "/root/HoshinoBot/hoshino/modules/priconne/arena/__init__.py", line 31, in <module>
    thumb_up_i = R.img('priconne/gadget/thumb-up-i.png').open().resize((16, 16), Image.LANCZOS)
  File "/root/HoshinoBot/hoshino/R.py", line 50, in open
    return Image.open(self.path)
  File "/usr/local/lib/python3.8/site-packages/PIL/Image.py", line 2904, in open
    fp = builtins.open(filename, "rb")
FileNotFoundError: [Errno 2] No such file or directory: './res/img/priconne/gadget/thumb-up-i.png'
[2021-01-21 20:50:34,435 hoshino] ERROR: 缺少图片资源：./res/img/priconne/gadget/thumb-up-i.png
[2021-01-21 20:50:34,435 pcr-arena] ERROR: [Errno 2] No such file or directory: './res/img/priconne/gadget/thumb-up-i.png'
Traceback (most recent call last):
  File "/root/HoshinoBot/hoshino/modules/priconne/arena/__init__.py", line 31, in <module>
    thumb_up_i = R.img('priconne/gadget/thumb-up-i.png').open().resize((16, 16), Image.LANCZOS)
  File "/root/HoshinoBot/hoshino/R.py", line 50, in open
    return Image.open(self.path)
  File "/usr/local/lib/python3.8/site-packages/PIL/Image.py", line 2904, in open
    fp = builtins.open(filename, "rb")
FileNotFoundError: [Errno 2] No such file or directory: './res/img/priconne/gadget/thumb-up-i.png'
[2021-01-21 20:57:14,310 hoshino] ERROR: 缺少图片资源：./res/img/priconne/gadget/thumb-up-i.png
[2021-01-21 20:57:14,310 pcr-arena] ERROR: [Errno 2] No such file or directory: './res/img/priconne/gadget/thumb-up-i.png'
Traceback (most recent call last):
  File "/root/HoshinoBot/hoshino/modules/priconne/arena/__init__.py", line 31, in <module>
    thumb_up_i = R.img('priconne/gadget/thumb-up-i.png').open().resize((16, 16), Image.LANCZOS)
  File "/root/HoshinoBot/hoshino/R.py", line 50, in open
    return Image.open(self.path)
  File "/usr/local/lib/python3.8/site-packages/PIL/Image.py", line 2904, in open
    fp = builtins.open(filename, "rb")
FileNotFoundError: [Errno 2] No such file or directory: './res/img/priconne/gadget/thumb-up-i.png'
[2021-01-21 21:14:29,874 hoshino] ERROR: 缺少图片资源：./res/img/priconne/gadget/thumb-up-i.png
[2021-01-21 21:14:29,875 pcr-arena] ERROR: [Errno 2] No such file or directory: './res/img/priconne/gadget/thumb-up-i.png'
Traceback (most recent call last):
  File "/root/HoshinoBot/hoshino/modules/priconne/arena/__init__.py", line 31, in <module>
    thumb_up_i = R.img('priconne/gadget/thumb-up-i.png').open().resize((16, 16), Image.LANCZOS)
  File "/root/HoshinoBot/hoshino/R.py", line 50, in open
    return Image.open(self.path)
  File "/usr/local/lib/python3.8/site-packages/PIL/Image.py", line 2904, in open
    fp = builtins.open(filename, "rb")
FileNotFoundError: [Errno 2] No such file or directory: './res/img/priconne/gadget/thumb-up-i.png'
[2021-01-21 21:14:41,181 mawo] ERROR: <class 'FileNotFoundError'> occured when xcw handling message -219743376.
[2021-01-21 21:14:41,181 mawo] ERROR: [Errno 2] No such file or directory: './res/record/mawo'
Traceback (most recent call last):
  File "/root/HoshinoBot/hoshino/msghandler.py", line 28, in handle_message
    await sf.func(bot, event)
  File "/root/HoshinoBot/hoshino/service.py", line 218, in wrapper
    return await func(bot, event)
  File "/root/HoshinoBot/hoshino/modules/xcw/xcw.py", line 26, in xcw
    file = get_xcw()
  File "/root/HoshinoBot/hoshino/modules/xcw/xcw.py", line 17, in get_xcw
    files = os.listdir(xcw_folder)
FileNotFoundError: [Errno 2] No such file or directory: './res/record/mawo'
[2021-01-21 21:15:19,071 mawo] ERROR: <class 'FileNotFoundError'> occured when xcw handling message 211967771.
[2021-01-21 21:15:19,071 mawo] ERROR: [Errno 2] No such file or directory: './res/record/mawo'
Traceback (most recent call last):
  File "/root/HoshinoBot/hoshino/msghandler.py", line 28, in handle_message
    await sf.func(bot, event)
  File "/root/HoshinoBot/hoshino/service.py", line 218, in wrapper
    return await func(bot, event)
  File "/root/HoshinoBot/hoshino/modules/xcw/xcw.py", line 26, in xcw
    file = get_xcw()
  File "/root/HoshinoBot/hoshino/modules/xcw/xcw.py", line 17, in get_xcw
    files = os.listdir(xcw_folder)
FileNotFoundError: [Errno 2] No such file or directory: './res/record/mawo'
[2021-01-21 21:17:04,214 mawo] ERROR: 发送失败
[2021-01-21 21:36:11,468 hoshino] ERROR: 缺少图片资源：./res/img/priconne/gadget/thumb-up-i.png
[2021-01-21 21:36:11,469 pcr-arena] ERROR: [Errno 2] No such file or directory: './res/img/priconne/gadget/thumb-up-i.png'
Traceback (most recent call last):
  File "/root/HoshinoBot/hoshino/modules/priconne/arena/__init__.py", line 31, in <module>
    thumb_up_i = R.img('priconne/gadget/thumb-up-i.png').open().resize((16, 16), Image.LANCZOS)
  File "/root/HoshinoBot/hoshino/R.py", line 50, in open
    return Image.open(self.path)
  File "/usr/local/lib/python3.8/site-packages/PIL/Image.py", line 2904, in open
    fp = builtins.open(filename, "rb")
FileNotFoundError: [Errno 2] No such file or directory: './res/img/priconne/gadget/thumb-up-i.png'
[2021-01-21 21:36:19,469 mawo] ERROR: 发送失败
[2021-01-21 21:38:40,807 hoshino] ERROR: 缺少图片资源：./res/img/priconne/gadget/thumb-up-i.png
[2021-01-21 21:38:40,807 pcr-arena] ERROR: [Errno 2] No such file or directory: './res/img/priconne/gadget/thumb-up-i.png'
Traceback (most recent call last):
  File "/root/HoshinoBot/hoshino/modules/priconne/arena/__init__.py", line 31, in <module>
    thumb_up_i = R.img('priconne/gadget/thumb-up-i.png').open().resize((16, 16), Image.LANCZOS)
  File "/root/HoshinoBot/hoshino/R.py", line 50, in open
    return Image.open(self.path)
  File "/usr/local/lib/python3.8/site-packages/PIL/Image.py", line 2904, in open
    fp = builtins.open(filename, "rb")
FileNotFoundError: [Errno 2] No such file or directory: './res/img/priconne/gadget/thumb-up-i.png'
[2021-01-21 21:40:16,562 mawo] ERROR: 发送失败
[2021-01-21 22:13:38,242 hoshino] ERROR: 缺少图片资源：./res/img/priconne/gadget/thumb-up-i.png
[2021-01-21 22:13:38,242 pcr-arena] ERROR: [Errno 2] No such file or directory: './res/img/priconne/gadget/thumb-up-i.png'
Traceback (most recent call last):
  File "/root/HoshinoBot/hoshino/modules/priconne/arena/__init__.py", line 31, in <module>
    thumb_up_i = R.img('priconne/gadget/thumb-up-i.png').open().resize((16, 16), Image.LANCZOS)
  File "/root/HoshinoBot/hoshino/R.py", line 50, in open
    return Image.open(self.path)
  File "/usr/local/lib/python3.8/site-packages/PIL/Image.py", line 2904, in open
    fp = builtins.open(filename, "rb")
FileNotFoundError: [Errno 2] No such file or directory: './res/img/priconne/gadget/thumb-up-i.png'
[2021-01-21 22:13:52,360 mawo] ERROR: 发送失败
[2021-01-21 22:19:08,001 mawo] ERROR: 发送失败
[2021-01-21 22:20:08,741 hoshino] ERROR: 缺少图片资源：./res/img/priconne/gadget/thumb-up-i.png
[2021-01-21 22:20:08,741 pcr-arena] ERROR: [Errno 2] No such file or directory: './res/img/priconne/gadget/thumb-up-i.png'
Traceback (most recent call last):
  File "/root/HoshinoBot/hoshino/modules/priconne/arena/__init__.py", line 31, in <module>
    thumb_up_i = R.img('priconne/gadget/thumb-up-i.png').open().resize((16, 16), Image.LANCZOS)
  File "/root/HoshinoBot/hoshino/R.py", line 50, in open
    return Image.open(self.path)
  File "/usr/local/lib/python3.8/site-packages/PIL/Image.py", line 2904, in open
    fp = builtins.open(filename, "rb")
FileNotFoundError: [Errno 2] No such file or directory: './res/img/priconne/gadget/thumb-up-i.png'
[2021-01-21 22:20:26,045 mawo] ERROR: 发送失败
[2021-01-21 22:20:32,541 mawo] ERROR: 发送失败
[2021-01-21 22:23:49,835 mawo] ERROR: 发送失败
[2021-01-21 23:12:09,688 mawo] ERROR: 发送失败
[2021-01-21 23:12:36,818 mawo] ERROR: 发送失败
[2021-01-21 23:13:32,802 mawo] ERROR: 发送失败
[2021-01-21 23:14:14,868 mawo] ERROR: 发送失败
[2021-01-21 23:27:30,352 mawo] ERROR: 发送失败
[2021-01-21 23:57:40,229 mawo] ERROR: 发送失败
[2021-01-22 00:07:03,852 hoshino] ERROR: 缺少图片资源：./res/img/priconne/gadget/thumb-up-i.png
[2021-01-22 00:07:03,852 pcr-arena] ERROR: [Errno 2] No such file or directory: './res/img/priconne/gadget/thumb-up-i.png'
Traceback (most recent call last):
  File "/root/HoshinoBot/hoshino/modules/priconne/arena/__init__.py", line 31, in <module>
    thumb_up_i = R.img('priconne/gadget/thumb-up-i.png').open().resize((16, 16), Image.LANCZOS)
  File "/root/HoshinoBot/hoshino/R.py", line 50, in open
    return Image.open(self.path)
  File "/usr/local/lib/python3.8/site-packages/PIL/Image.py", line 2904, in open
    fp = builtins.open(filename, "rb")
FileNotFoundError: [Errno 2] No such file or directory: './res/img/priconne/gadget/thumb-up-i.png'
[2021-01-22 00:07:21,160 mawo] ERROR: 发送失败
[2021-01-22 00:09:12,696 hoshino] ERROR: 缺少图片资源：./res/img/priconne/gadget/thumb-up-i.png
[2021-01-22 00:09:12,697 pcr-arena] ERROR: [Errno 2] No such file or directory: './res/img/priconne/gadget/thumb-up-i.png'
Traceback (most recent call last):
  File "/root/HoshinoBot/hoshino/modules/priconne/arena/__init__.py", line 31, in <module>
    thumb_up_i = R.img('priconne/gadget/thumb-up-i.png').open().resize((16, 16), Image.LANCZOS)
  File "/root/HoshinoBot/hoshino/R.py", line 50, in open
    return Image.open(self.path)
  File "/usr/local/lib/python3.8/site-packages/PIL/Image.py", line 2904, in open
    fp = builtins.open(filename, "rb")
FileNotFoundError: [Errno 2] No such file or directory: './res/img/priconne/gadget/thumb-up-i.png'
[2021-01-22 00:09:40,721 mawo] ERROR: 发送失败
[2021-01-22 00:09:40,721 mawo] ERROR: ./res/record/mawo
[2021-01-22 00:09:40,721 mawo] ERROR: <hoshino.service.Service object at 0x7fc2be693430>
[2021-01-22 00:11:49,842 hoshino] ERROR: 缺少图片资源：./res/img/priconne/gadget/thumb-up-i.png
[2021-01-22 00:11:49,842 pcr-arena] ERROR: [Errno 2] No such file or directory: './res/img/priconne/gadget/thumb-up-i.png'
Traceback (most recent call last):
  File "/root/HoshinoBot/hoshino/modules/priconne/arena/__init__.py", line 31, in <module>
    thumb_up_i = R.img('priconne/gadget/thumb-up-i.png').open().resize((16, 16), Image.LANCZOS)
  File "/root/HoshinoBot/hoshino/R.py", line 50, in open
    return Image.open(self.path)
  File "/usr/local/lib/python3.8/site-packages/PIL/Image.py", line 2904, in open
    fp = builtins.open(filename, "rb")
FileNotFoundError: [Errno 2] No such file or directory: './res/img/priconne/gadget/thumb-up-i.png'
[2021-01-22 00:11:56,288 mawo] ERROR: 发送失败
[2021-01-22 00:11:56,289 mawo] ERROR: ./res/record/mawo
[2021-01-22 00:11:56,289 mawo] ERROR: <hoshino.R.ResObj object at 0x7fc82983b070>
[2021-01-22 00:12:07,684 mawo] ERROR: 发送失败
[2021-01-22 00:12:07,684 mawo] ERROR: ./res/record/mawo
[2021-01-22 00:12:07,685 mawo] ERROR: <hoshino.R.ResObj object at 0x7fc82983b9a0>
[2021-01-22 00:15:21,553 hoshino] ERROR: 缺少图片资源：./res/img/priconne/gadget/thumb-up-i.png
[2021-01-22 00:15:21,554 pcr-arena] ERROR: [Errno 2] No such file or directory: './res/img/priconne/gadget/thumb-up-i.png'
Traceback (most recent call last):
  File "/root/HoshinoBot/hoshino/modules/priconne/arena/__init__.py", line 31, in <module>
    thumb_up_i = R.img('priconne/gadget/thumb-up-i.png').open().resize((16, 16), Image.LANCZOS)
  File "/root/HoshinoBot/hoshino/R.py", line 50, in open
    return Image.open(self.path)
  File "/usr/local/lib/python3.8/site-packages/PIL/Image.py", line 2904, in open
    fp = builtins.open(filename, "rb")
FileNotFoundError: [Errno 2] No such file or directory: './res/img/priconne/gadget/thumb-up-i.png'
[2021-01-22 00:15:30,589 mawo] ERROR: 发送失败
[2021-01-22 00:15:30,590 mawo] ERROR: ./res/record/mawo
[2021-01-22 00:15:30,590 mawo] ERROR: file:////root/HoshinoBot/res/record/mawo/都怪你，真是的！.m4a
[2021-01-22 00:15:50,990 mawo] ERROR: 发送失败
[2021-01-22 00:15:50,990 mawo] ERROR: ./res/record/mawo
[2021-01-22 00:15:50,990 mawo] ERROR: file:////root/HoshinoBot/res/record/mawo/放开我.m4a
[2021-01-22 00:19:00,378 hoshino] ERROR: 缺少图片资源：./res/img/priconne/gadget/thumb-up-i.png
[2021-01-22 00:19:00,379 pcr-arena] ERROR: [Errno 2] No such file or directory: './res/img/priconne/gadget/thumb-up-i.png'
Traceback (most recent call last):
  File "/root/HoshinoBot/hoshino/modules/priconne/arena/__init__.py", line 31, in <module>
    thumb_up_i = R.img('priconne/gadget/thumb-up-i.png').open().resize((16, 16), Image.LANCZOS)
  File "/root/HoshinoBot/hoshino/R.py", line 50, in open
    return Image.open(self.path)
  File "/usr/local/lib/python3.8/site-packages/PIL/Image.py", line 2904, in open
    fp = builtins.open(filename, "rb")
FileNotFoundError: [Errno 2] No such file or directory: './res/img/priconne/gadget/thumb-up-i.png'
[2021-01-22 00:19:25,617 mawo] ERROR: 发送失败
[2021-01-22 00:19:25,617 mawo] ERROR: ./res/record/mawo
[2021-01-22 00:19:25,618 mawo] ERROR: file:////root/HoshinoBot/res/record/mawo/我懂了，你是变态吧.mp3
[2021-01-22 00:33:21,772 hoshino] ERROR: 缺少图片资源：./res/img/priconne/gadget/thumb-up-i.png
[2021-01-22 00:33:21,773 pcr-arena] ERROR: [Errno 2] No such file or directory: './res/img/priconne/gadget/thumb-up-i.png'
Traceback (most recent call last):
  File "/root/HoshinoBot/hoshino/modules/priconne/arena/__init__.py", line 31, in <module>
    thumb_up_i = R.img('priconne/gadget/thumb-up-i.png').open().resize((16, 16), Image.LANCZOS)
  File "/root/HoshinoBot/hoshino/R.py", line 50, in open
    return Image.open(self.path)
  File "/usr/local/lib/python3.8/site-packages/PIL/Image.py", line 2904, in open
    fp = builtins.open(filename, "rb")
FileNotFoundError: [Errno 2] No such file or directory: './res/img/priconne/gadget/thumb-up-i.png'
[2021-01-22 00:40:16,720 hoshino] ERROR: 缺少图片资源：./res/img/priconne/gadget/thumb-up-i.png
[2021-01-22 00:40:16,721 pcr-arena] ERROR: [Errno 2] No such file or directory: './res/img/priconne/gadget/thumb-up-i.png'
Traceback (most recent call last):
  File "/root/HoshinoBot/hoshino/modules/priconne/arena/__init__.py", line 31, in <module>
    thumb_up_i = R.img('priconne/gadget/thumb-up-i.png').open().resize((16, 16), Image.LANCZOS)
  File "/root/HoshinoBot/hoshino/R.py", line 50, in open
    return Image.open(self.path)
  File "/usr/local/lib/python3.8/site-packages/PIL/Image.py", line 2904, in open
    fp = builtins.open(filename, "rb")
FileNotFoundError: [Errno 2] No such file or directory: './res/img/priconne/gadget/thumb-up-i.png'
[2021-01-22 00:42:11,896 echo] ERROR: <class 'aiocqhttp.exceptions.NetworkError'> occured when duiya handling message -257931991.
[2021-01-22 00:42:11,897 echo] ERROR: WebSocket API call timeout
Traceback (most recent call last):
  File "/usr/local/lib/python3.8/site-packages/aiocqhttp/api_impl.py", line 118, in fetch
    return await asyncio.wait_for(future, timeout_sec)
  File "/usr/local/lib/python3.8/asyncio/tasks.py", line 498, in wait_for
    raise exceptions.TimeoutError()
asyncio.exceptions.TimeoutError

During handling of the above exception, another exception occurred:

Traceback (most recent call last):
  File "/root/HoshinoBot/hoshino/msghandler.py", line 28, in handle_message
    await sf.func(bot, event)
  File "/root/HoshinoBot/hoshino/service.py", line 218, in wrapper
    return await func(bot, event)
  File "/root/HoshinoBot/hoshino/modules/echo/echo.py", line 38, in duiya
    await bot.send(event, rec)
  File "/usr/local/lib/python3.8/site-packages/aiocqhttp/__init__.py", line 256, in send
    return await self.send_msg(**params)
  File "/usr/local/lib/python3.8/site-packages/aiocqhttp/__init__.py", line 223, in call_action
    return await self._api.call_action(action=action, **params)
  File "/usr/local/lib/python3.8/site-packages/aiocqhttp/api_impl.py", line 186, in call_action
    result = await self._wsr_api.call_action(action, **params)
  File "/usr/local/lib/python3.8/site-packages/aiocqhttp/api_impl.py", line 162, in call_action
    await ResultStore.fetch(seq, self._timeout_sec))
  File "/usr/local/lib/python3.8/site-packages/aiocqhttp/api_impl.py", line 122, in fetch
    raise NetworkError('WebSocket API call timeout')
aiocqhttp.exceptions.NetworkError: WebSocket API call timeout
[2021-01-22 01:20:35,985 hoshino] ERROR: 缺少图片资源：./res/img/priconne/gadget/thumb-up-i.png
[2021-01-22 01:20:35,986 pcr-arena] ERROR: [Errno 2] No such file or directory: './res/img/priconne/gadget/thumb-up-i.png'
Traceback (most recent call last):
  File "/root/HoshinoBot/hoshino/modules/priconne/arena/__init__.py", line 31, in <module>
    thumb_up_i = R.img('priconne/gadget/thumb-up-i.png').open().resize((16, 16), Image.LANCZOS)
  File "/root/HoshinoBot/hoshino/R.py", line 50, in open
    return Image.open(self.path)
  File "/usr/local/lib/python3.8/site-packages/PIL/Image.py", line 2904, in open
    fp = builtins.open(filename, "rb")
FileNotFoundError: [Errno 2] No such file or directory: './res/img/priconne/gadget/thumb-up-i.png'
[2021-01-22 01:25:03,565 pcr-arena] ERROR: Arena query failed.
Response={'code': 103, 'message': '103', 'version': '20210118'}
Payload={'_sign': 'a', 'def': [101201, 101801, 100601, 170101, 100701], 'nonce': 'a', 'page': 1, 'sort': 1, 'ts': 1611249903, 'region': 1}
[2021-01-22 13:38:08,190 hoshino] ERROR: 缺少图片资源：./res/img/priconne/gadget/thumb-up-i.png
[2021-01-22 13:38:08,191 pcr-arena] ERROR: [Errno 2] No such file or directory: './res/img/priconne/gadget/thumb-up-i.png'
Traceback (most recent call last):
  File "/root/HoshinoBot/hoshino/modules/priconne/arena/__init__.py", line 31, in <module>
    thumb_up_i = R.img('priconne/gadget/thumb-up-i.png').open().resize((16, 16), Image.LANCZOS)
  File "/root/HoshinoBot/hoshino/R.py", line 50, in open
    return Image.open(self.path)
  File "/usr/local/lib/python3.8/site-packages/PIL/Image.py", line 2904, in open
    fp = builtins.open(filename, "rb")
FileNotFoundError: [Errno 2] No such file or directory: './res/img/priconne/gadget/thumb-up-i.png'
[2021-01-22 15:25:08,797 hoshino] CRITICAL: Self: 1142643359, Message -889387640 from 123337671: cnm
[2021-01-22 15:25:08,952 hoshino] ERROR: 禁言失败 retcode=100
[2021-01-22 17:19:53,186 hoshino] CRITICAL: Self: 1142643359, Message -35644086 from 123337671: cnm
[2021-01-22 17:19:53,427 hoshino] ERROR: 禁言失败 retcode=100
[2021-01-22 17:23:16,677 hoshino] ERROR: 缺少图片资源：./res/img/priconne/gadget/thumb-up-i.png
[2021-01-22 17:23:16,677 pcr-arena] ERROR: [Errno 2] No such file or directory: './res/img/priconne/gadget/thumb-up-i.png'
Traceback (most recent call last):
  File "/root/HoshinoBot/hoshino/modules/priconne/arena/__init__.py", line 31, in <module>
    thumb_up_i = R.img('priconne/gadget/thumb-up-i.png').open().resize((16, 16), Image.LANCZOS)
  File "/root/HoshinoBot/hoshino/R.py", line 50, in open
    return Image.open(self.path)
  File "/usr/local/lib/python3.8/site-packages/PIL/Image.py", line 2904, in open
    fp = builtins.open(filename, "rb")
FileNotFoundError: [Errno 2] No such file or directory: './res/img/priconne/gadget/thumb-up-i.png'
[2021-01-22 17:23:26,399 chara] ERROR: Failed to download https://redive.estertion.win/icon/unit/113761.webp. HTTP 404
[2021-01-22 17:23:33,577 pcr-avatar-guess] ERROR: <class 'requests.exceptions.ConnectionError'> occured when avatar_guess handling message -728435473.
[2021-01-22 17:23:33,578 pcr-avatar-guess] ERROR: HTTPSConnectionPool(host='redive.estertion.win', port=443): Read timed out.
Traceback (most recent call last):
  File "/usr/local/lib/python3.8/site-packages/urllib3/response.py", line 438, in _error_catcher
    yield
  File "/usr/local/lib/python3.8/site-packages/urllib3/response.py", line 519, in read
    data = self._fp.read(amt) if not fp_closed else b""
  File "/usr/local/lib/python3.8/http/client.py", line 458, in read
    n = self.readinto(b)
  File "/usr/local/lib/python3.8/http/client.py", line 502, in readinto
    n = self.fp.readinto(b)
  File "/usr/local/lib/python3.8/socket.py", line 669, in readinto
    return self._sock.recv_into(b)
  File "/usr/local/lib/python3.8/ssl.py", line 1241, in recv_into
    return self.read(nbytes, buffer)
  File "/usr/local/lib/python3.8/ssl.py", line 1099, in read
    return self._sslobj.read(len, buffer)
socket.timeout: The read operation timed out

During handling of the above exception, another exception occurred:

Traceback (most recent call last):
  File "/usr/local/lib/python3.8/site-packages/requests/models.py", line 753, in generate
    for chunk in self.raw.stream(chunk_size, decode_content=True):
  File "/usr/local/lib/python3.8/site-packages/urllib3/response.py", line 576, in stream
    data = self.read(amt=amt, decode_content=decode_content)
  File "/usr/local/lib/python3.8/site-packages/urllib3/response.py", line 541, in read
    raise IncompleteRead(self._fp_bytes_read, self.length_remaining)
  File "/usr/local/lib/python3.8/contextlib.py", line 131, in __exit__
    self.gen.throw(type, value, traceback)
  File "/usr/local/lib/python3.8/site-packages/urllib3/response.py", line 443, in _error_catcher
    raise ReadTimeoutError(self._pool, None, "Read timed out.")
urllib3.exceptions.ReadTimeoutError: HTTPSConnectionPool(host='redive.estertion.win', port=443): Read timed out.

During handling of the above exception, another exception occurred:

Traceback (most recent call last):
  File "/root/HoshinoBot/hoshino/msghandler.py", line 28, in handle_message
    await sf.func(bot, event)
  File "/root/HoshinoBot/hoshino/service.py", line 218, in wrapper
    return await func(bot, event)
  File "/root/HoshinoBot/hoshino/modules/priconne/games/avatar_guess.py", line 58, in avatar_guess
    img = c.icon.open()
  File "/root/HoshinoBot/hoshino/modules/priconne/chara.py", line 154, in icon
    download_chara_icon(self.id, 3)
  File "/root/HoshinoBot/hoshino/modules/priconne/chara.py", line 122, in download_chara_icon
    img = Image.open(BytesIO(rsp.content))
  File "/usr/local/lib/python3.8/site-packages/requests/models.py", line 831, in content
    self._content = b''.join(self.iter_content(CONTENT_CHUNK_SIZE)) or b''
  File "/usr/local/lib/python3.8/site-packages/requests/models.py", line 760, in generate
    raise ConnectionError(e)
requests.exceptions.ConnectionError: HTTPSConnectionPool(host='redive.estertion.win', port=443): Read timed out.
[2021-01-22 18:12:02,338 hoshino] ERROR: 缺少图片资源：./res/img/priconne/gadget/thumb-up-i.png
[2021-01-22 18:12:02,339 pcr-arena] ERROR: [Errno 2] No such file or directory: './res/img/priconne/gadget/thumb-up-i.png'
Traceback (most recent call last):
  File "/root/HoshinoBot/hoshino/modules/priconne/arena/__init__.py", line 31, in <module>
    thumb_up_i = R.img('priconne/gadget/thumb-up-i.png').open().resize((16, 16), Image.LANCZOS)
  File "/root/HoshinoBot/hoshino/R.py", line 50, in open
    return Image.open(self.path)
  File "/usr/local/lib/python3.8/site-packages/PIL/Image.py", line 2904, in open
    fp = builtins.open(filename, "rb")
FileNotFoundError: [Errno 2] No such file or directory: './res/img/priconne/gadget/thumb-up-i.png'
[2021-01-22 18:40:47,288 nonebot] ERROR: Failed to import "hoshino.modules.groupmaster.chat", error: on_fullmatch() got multiple values for argument 'only_to_me'
[2021-01-22 18:40:47,289 nonebot] ERROR: on_fullmatch() got multiple values for argument 'only_to_me'
Traceback (most recent call last):
  File "/usr/local/lib/python3.8/site-packages/nonebot/plugin.py", line 274, in load_plugin
    module = importlib.import_module(module_path)
  File "/usr/local/lib/python3.8/importlib/__init__.py", line 127, in import_module
    return _bootstrap._gcd_import(name[level:], package, level)
  File "<frozen importlib._bootstrap>", line 1014, in _gcd_import
  File "<frozen importlib._bootstrap>", line 991, in _find_and_load
  File "<frozen importlib._bootstrap>", line 975, in _find_and_load_unlocked
  File "<frozen importlib._bootstrap>", line 671, in _load_unlocked
  File "<frozen importlib._bootstrap_external>", line 783, in exec_module
  File "<frozen importlib._bootstrap>", line 219, in _call_with_frames_removed
  File "/root/HoshinoBot/hoshino/modules/groupmaster/chat.py", line 59, in <module>
    @sv.on_fullmatch('ue','春田', only_to_me=True)
TypeError: on_fullmatch() got multiple values for argument 'only_to_me'
[2021-01-22 18:40:47,675 hoshino] ERROR: 缺少图片资源：./res/img/priconne/gadget/thumb-up-i.png
[2021-01-22 18:40:47,675 pcr-arena] ERROR: [Errno 2] No such file or directory: './res/img/priconne/gadget/thumb-up-i.png'
Traceback (most recent call last):
  File "/root/HoshinoBot/hoshino/modules/priconne/arena/__init__.py", line 31, in <module>
    thumb_up_i = R.img('priconne/gadget/thumb-up-i.png').open().resize((16, 16), Image.LANCZOS)
  File "/root/HoshinoBot/hoshino/R.py", line 50, in open
    return Image.open(self.path)
  File "/usr/local/lib/python3.8/site-packages/PIL/Image.py", line 2904, in open
    fp = builtins.open(filename, "rb")
FileNotFoundError: [Errno 2] No such file or directory: './res/img/priconne/gadget/thumb-up-i.png'
[2021-01-22 18:42:23,328 hoshino] ERROR: 缺少图片资源：./res/img/priconne/gadget/thumb-up-i.png
[2021-01-22 18:42:23,328 pcr-arena] ERROR: [Errno 2] No such file or directory: './res/img/priconne/gadget/thumb-up-i.png'
Traceback (most recent call last):
  File "/root/HoshinoBot/hoshino/modules/priconne/arena/__init__.py", line 31, in <module>
    thumb_up_i = R.img('priconne/gadget/thumb-up-i.png').open().resize((16, 16), Image.LANCZOS)
  File "/root/HoshinoBot/hoshino/R.py", line 50, in open
    return Image.open(self.path)
  File "/usr/local/lib/python3.8/site-packages/PIL/Image.py", line 2904, in open
    fp = builtins.open(filename, "rb")
FileNotFoundError: [Errno 2] No such file or directory: './res/img/priconne/gadget/thumb-up-i.png'
[2021-01-22 18:42:23,693 nonebot] ERROR: Failed to import "hoshino.modules.groupmaster.chat", error: on_keyword() got multiple values for argument 'only_to_me'
[2021-01-22 18:42:23,694 nonebot] ERROR: on_keyword() got multiple values for argument 'only_to_me'
Traceback (most recent call last):
  File "/usr/local/lib/python3.8/site-packages/nonebot/plugin.py", line 274, in load_plugin
    module = importlib.import_module(module_path)
  File "/usr/local/lib/python3.8/importlib/__init__.py", line 127, in import_module
    return _bootstrap._gcd_import(name[level:], package, level)
  File "<frozen importlib._bootstrap>", line 1014, in _gcd_import
  File "<frozen importlib._bootstrap>", line 991, in _find_and_load
  File "<frozen importlib._bootstrap>", line 975, in _find_and_load_unlocked
  File "<frozen importlib._bootstrap>", line 671, in _load_unlocked
  File "<frozen importlib._bootstrap_external>", line 783, in exec_module
  File "<frozen importlib._bootstrap>", line 219, in _call_with_frames_removed
  File "/root/HoshinoBot/hoshino/modules/groupmaster/chat.py", line 59, in <module>
    @sv.on_keyword('ue','春田', only_to_me=True)
TypeError: on_keyword() got multiple values for argument 'only_to_me'
[2021-01-22 19:43:43,482 hoshino] ERROR: 缺少图片资源：./res/img/priconne/gadget/thumb-up-i.png
[2021-01-22 19:43:43,482 pcr-arena] ERROR: [Errno 2] No such file or directory: './res/img/priconne/gadget/thumb-up-i.png'
Traceback (most recent call last):
  File "/root/HoshinoBot/hoshino/modules/priconne/arena/__init__.py", line 31, in <module>
    thumb_up_i = R.img('priconne/gadget/thumb-up-i.png').open().resize((16, 16), Image.LANCZOS)
  File "/root/HoshinoBot/hoshino/R.py", line 50, in open
    return Image.open(self.path)
  File "/usr/local/lib/python3.8/site-packages/PIL/Image.py", line 2904, in open
    fp = builtins.open(filename, "rb")
FileNotFoundError: [Errno 2] No such file or directory: './res/img/priconne/gadget/thumb-up-i.png'
[2021-01-22 19:43:43,886 nonebot] ERROR: Failed to import "hoshino.modules.groupmaster.chat", error: on_keyword() got multiple values for argument 'only_to_me'
[2021-01-22 19:43:43,887 nonebot] ERROR: on_keyword() got multiple values for argument 'only_to_me'
Traceback (most recent call last):
  File "/usr/local/lib/python3.8/site-packages/nonebot/plugin.py", line 274, in load_plugin
    module = importlib.import_module(module_path)
  File "/usr/local/lib/python3.8/importlib/__init__.py", line 127, in import_module
    return _bootstrap._gcd_import(name[level:], package, level)
  File "<frozen importlib._bootstrap>", line 1014, in _gcd_import
  File "<frozen importlib._bootstrap>", line 991, in _find_and_load
  File "<frozen importlib._bootstrap>", line 975, in _find_and_load_unlocked
  File "<frozen importlib._bootstrap>", line 671, in _load_unlocked
  File "<frozen importlib._bootstrap_external>", line 783, in exec_module
  File "<frozen importlib._bootstrap>", line 219, in _call_with_frames_removed
  File "/root/HoshinoBot/hoshino/modules/groupmaster/chat.py", line 59, in <module>
    @sv.on_keyword('ue','春田', only_to_me=True)
TypeError: on_keyword() got multiple values for argument 'only_to_me'
[2021-01-22 19:44:27,727 setu_mix] ERROR: <class 'IndexError'> occured when send_random_setu handling message 383386137.
[2021-01-22 19:44:27,727 setu_mix] ERROR: Cannot choose from an empty sequence
Traceback (most recent call last):
  File "/root/HoshinoBot/hoshino/msghandler.py", line 28, in handle_message
    await sf.func(bot, event)
  File "/root/HoshinoBot/hoshino/modules/setu_mix/__init__.py", line 106, in send_random_setu
    msg = await get_setu(gid)
  File "/root/HoshinoBot/hoshino/modules/setu_mix/base.py", line 52, in get_setu
    image = await lolicon_get_setu(0)
  File "/root/HoshinoBot/hoshino/modules/setu_mix/lolicon.py", line 257, in lolicon_get_setu
    return get_setu_native(r18)
  File "/root/HoshinoBot/hoshino/modules/setu_mix/lolicon.py", line 203, in get_setu_native
    fn = random.choice(os.listdir(res.path))
  File "/usr/local/lib/python3.8/random.py", line 290, in choice
    raise IndexError('Cannot choose from an empty sequence') from None
IndexError: Cannot choose from an empty sequence
[2021-01-22 19:44:52,066 setu_mix] ERROR: <class 'IndexError'> occured when send_random_setu handling message -2040193144.
[2021-01-22 19:44:52,067 setu_mix] ERROR: Cannot choose from an empty sequence
Traceback (most recent call last):
  File "/root/HoshinoBot/hoshino/msghandler.py", line 28, in handle_message
    await sf.func(bot, event)
  File "/root/HoshinoBot/hoshino/modules/setu_mix/__init__.py", line 106, in send_random_setu
    msg = await get_setu(gid)
  File "/root/HoshinoBot/hoshino/modules/setu_mix/base.py", line 52, in get_setu
    image = await lolicon_get_setu(0)
  File "/root/HoshinoBot/hoshino/modules/setu_mix/lolicon.py", line 257, in lolicon_get_setu
    return get_setu_native(r18)
  File "/root/HoshinoBot/hoshino/modules/setu_mix/lolicon.py", line 203, in get_setu_native
    fn = random.choice(os.listdir(res.path))
  File "/usr/local/lib/python3.8/random.py", line 290, in choice
    raise IndexError('Cannot choose from an empty sequence') from None
IndexError: Cannot choose from an empty sequence
[2021-01-22 19:47:45,859 nonebot] ERROR: Failed to import "hoshino.modules.groupmaster.chat", error: on_keyword() got multiple values for argument 'only_to_me'
[2021-01-22 19:47:45,859 nonebot] ERROR: on_keyword() got multiple values for argument 'only_to_me'
Traceback (most recent call last):
  File "/usr/local/lib/python3.8/site-packages/nonebot/plugin.py", line 274, in load_plugin
    module = importlib.import_module(module_path)
  File "/usr/local/lib/python3.8/importlib/__init__.py", line 127, in import_module
    return _bootstrap._gcd_import(name[level:], package, level)
  File "<frozen importlib._bootstrap>", line 1014, in _gcd_import
  File "<frozen importlib._bootstrap>", line 991, in _find_and_load
  File "<frozen importlib._bootstrap>", line 975, in _find_and_load_unlocked
  File "<frozen importlib._bootstrap>", line 671, in _load_unlocked
  File "<frozen importlib._bootstrap_external>", line 783, in exec_module
  File "<frozen importlib._bootstrap>", line 219, in _call_with_frames_removed
  File "/root/HoshinoBot/hoshino/modules/groupmaster/chat.py", line 59, in <module>
    @sv.on_keyword('ue','春田', only_to_me=True)
TypeError: on_keyword() got multiple values for argument 'only_to_me'
[2021-01-22 19:47:46,014 hoshino] ERROR: 缺少图片资源：./res/img/priconne/gadget/thumb-up-i.png
[2021-01-22 19:47:46,014 pcr-arena] ERROR: [Errno 2] No such file or directory: './res/img/priconne/gadget/thumb-up-i.png'
Traceback (most recent call last):
  File "/root/HoshinoBot/hoshino/modules/priconne/arena/__init__.py", line 31, in <module>
    thumb_up_i = R.img('priconne/gadget/thumb-up-i.png').open().resize((16, 16), Image.LANCZOS)
  File "/root/HoshinoBot/hoshino/R.py", line 50, in open
    return Image.open(self.path)
  File "/usr/local/lib/python3.8/site-packages/PIL/Image.py", line 2904, in open
    fp = builtins.open(filename, "rb")
FileNotFoundError: [Errno 2] No such file or directory: './res/img/priconne/gadget/thumb-up-i.png'
[2021-01-22 20:17:51,082 nonebot] ERROR: Failed to import "hoshino.modules.groupmaster.chat", error: on_keyword() got multiple values for argument 'only_to_me'
[2021-01-22 20:17:51,082 nonebot] ERROR: on_keyword() got multiple values for argument 'only_to_me'
Traceback (most recent call last):
  File "/usr/local/lib/python3.8/site-packages/nonebot/plugin.py", line 274, in load_plugin
    module = importlib.import_module(module_path)
  File "/usr/local/lib/python3.8/importlib/__init__.py", line 127, in import_module
    return _bootstrap._gcd_import(name[level:], package, level)
  File "<frozen importlib._bootstrap>", line 1014, in _gcd_import
  File "<frozen importlib._bootstrap>", line 991, in _find_and_load
  File "<frozen importlib._bootstrap>", line 975, in _find_and_load_unlocked
  File "<frozen importlib._bootstrap>", line 671, in _load_unlocked
  File "<frozen importlib._bootstrap_external>", line 783, in exec_module
  File "<frozen importlib._bootstrap>", line 219, in _call_with_frames_removed
  File "/root/HoshinoBot/hoshino/modules/groupmaster/chat.py", line 59, in <module>
    @sv.on_keyword('ue','春田', only_to_me=True)
TypeError: on_keyword() got multiple values for argument 'only_to_me'
[2021-01-22 20:17:51,246 hoshino] ERROR: 缺少图片资源：./res/img/priconne/gadget/thumb-up-i.png
[2021-01-22 20:17:51,246 pcr-arena] ERROR: [Errno 2] No such file or directory: './res/img/priconne/gadget/thumb-up-i.png'
Traceback (most recent call last):
  File "/root/HoshinoBot/hoshino/modules/priconne/arena/__init__.py", line 31, in <module>
    thumb_up_i = R.img('priconne/gadget/thumb-up-i.png').open().resize((16, 16), Image.LANCZOS)
  File "/root/HoshinoBot/hoshino/R.py", line 50, in open
    return Image.open(self.path)
  File "/usr/local/lib/python3.8/site-packages/PIL/Image.py", line 2904, in open
    fp = builtins.open(filename, "rb")
FileNotFoundError: [Errno 2] No such file or directory: './res/img/priconne/gadget/thumb-up-i.png'
[2021-01-22 20:21:52,342 nonebot] ERROR: Failed to import "hoshino.modules.groupmaster.chat", error: on_keyword() got multiple values for argument 'only_to_me'
[2021-01-22 20:21:52,343 nonebot] ERROR: on_keyword() got multiple values for argument 'only_to_me'
Traceback (most recent call last):
  File "/usr/local/lib/python3.8/site-packages/nonebot/plugin.py", line 274, in load_plugin
    module = importlib.import_module(module_path)
  File "/usr/local/lib/python3.8/importlib/__init__.py", line 127, in import_module
    return _bootstrap._gcd_import(name[level:], package, level)
  File "<frozen importlib._bootstrap>", line 1014, in _gcd_import
  File "<frozen importlib._bootstrap>", line 991, in _find_and_load
  File "<frozen importlib._bootstrap>", line 975, in _find_and_load_unlocked
  File "<frozen importlib._bootstrap>", line 671, in _load_unlocked
  File "<frozen importlib._bootstrap_external>", line 783, in exec_module
  File "<frozen importlib._bootstrap>", line 219, in _call_with_frames_removed
  File "/root/HoshinoBot/hoshino/modules/groupmaster/chat.py", line 59, in <module>
    @sv.on_keyword('ue','春田', only_to_me=True)
TypeError: on_keyword() got multiple values for argument 'only_to_me'
[2021-01-22 20:21:52,544 hoshino] ERROR: 缺少图片资源：./res/img/priconne/gadget/thumb-up-i.png
[2021-01-22 20:21:52,544 pcr-arena] ERROR: [Errno 2] No such file or directory: './res/img/priconne/gadget/thumb-up-i.png'
Traceback (most recent call last):
  File "/root/HoshinoBot/hoshino/modules/priconne/arena/__init__.py", line 31, in <module>
    thumb_up_i = R.img('priconne/gadget/thumb-up-i.png').open().resize((16, 16), Image.LANCZOS)
  File "/root/HoshinoBot/hoshino/R.py", line 50, in open
    return Image.open(self.path)
  File "/usr/local/lib/python3.8/site-packages/PIL/Image.py", line 2904, in open
    fp = builtins.open(filename, "rb")
FileNotFoundError: [Errno 2] No such file or directory: './res/img/priconne/gadget/thumb-up-i.png'
[2021-01-22 20:39:26,930 hoshino] ERROR: 缺少图片资源：./res/img/priconne/gadget/thumb-up-i.png
[2021-01-22 20:39:26,934 pcr-arena] ERROR: [Errno 2] No such file or directory: './res/img/priconne/gadget/thumb-up-i.png'
Traceback (most recent call last):
  File "/root/HoshinoBot/hoshino/modules/priconne/arena/__init__.py", line 31, in <module>
    thumb_up_i = R.img('priconne/gadget/thumb-up-i.png').open().resize((16, 16), Image.LANCZOS)
  File "/root/HoshinoBot/hoshino/R.py", line 50, in open
    return Image.open(self.path)
  File "/usr/local/lib/python3.8/site-packages/PIL/Image.py", line 2904, in open
    fp = builtins.open(filename, "rb")
FileNotFoundError: [Errno 2] No such file or directory: './res/img/priconne/gadget/thumb-up-i.png'
[2021-01-22 20:39:27,313 nonebot] ERROR: Failed to import "hoshino.modules.groupmaster.chat", error: on_keyword() got multiple values for argument 'only_to_me'
[2021-01-22 20:39:27,313 nonebot] ERROR: on_keyword() got multiple values for argument 'only_to_me'
Traceback (most recent call last):
  File "/usr/local/lib/python3.8/site-packages/nonebot/plugin.py", line 274, in load_plugin
    module = importlib.import_module(module_path)
  File "/usr/local/lib/python3.8/importlib/__init__.py", line 127, in import_module
    return _bootstrap._gcd_import(name[level:], package, level)
  File "<frozen importlib._bootstrap>", line 1014, in _gcd_import
  File "<frozen importlib._bootstrap>", line 991, in _find_and_load
  File "<frozen importlib._bootstrap>", line 975, in _find_and_load_unlocked
  File "<frozen importlib._bootstrap>", line 671, in _load_unlocked
  File "<frozen importlib._bootstrap_external>", line 783, in exec_module
  File "<frozen importlib._bootstrap>", line 219, in _call_with_frames_removed
  File "/root/HoshinoBot/hoshino/modules/groupmaster/chat.py", line 59, in <module>
    @sv.on_keyword('ue','春田', only_to_me=True)
TypeError: on_keyword() got multiple values for argument 'only_to_me'
[2021-01-22 20:55:35,744 nonebot] ERROR: Failed to import "hoshino.modules.groupmaster.chat", error: on_keyword() got multiple values for argument 'only_to_me'
[2021-01-22 20:55:35,744 nonebot] ERROR: on_keyword() got multiple values for argument 'only_to_me'
Traceback (most recent call last):
  File "/usr/local/lib/python3.8/site-packages/nonebot/plugin.py", line 274, in load_plugin
    module = importlib.import_module(module_path)
  File "/usr/local/lib/python3.8/importlib/__init__.py", line 127, in import_module
    return _bootstrap._gcd_import(name[level:], package, level)
  File "<frozen importlib._bootstrap>", line 1014, in _gcd_import
  File "<frozen importlib._bootstrap>", line 991, in _find_and_load
  File "<frozen importlib._bootstrap>", line 975, in _find_and_load_unlocked
  File "<frozen importlib._bootstrap>", line 671, in _load_unlocked
  File "<frozen importlib._bootstrap_external>", line 783, in exec_module
  File "<frozen importlib._bootstrap>", line 219, in _call_with_frames_removed
  File "/root/HoshinoBot/hoshino/modules/groupmaster/chat.py", line 59, in <module>
    @sv.on_keyword('ue','春田', only_to_me=True)
TypeError: on_keyword() got multiple values for argument 'only_to_me'
[2021-01-22 20:55:36,030 hoshino] ERROR: 缺少图片资源：./res/img/priconne/gadget/thumb-up-i.png
[2021-01-22 20:55:36,031 pcr-arena] ERROR: [Errno 2] No such file or directory: './res/img/priconne/gadget/thumb-up-i.png'
Traceback (most recent call last):
  File "/root/HoshinoBot/hoshino/modules/priconne/arena/__init__.py", line 31, in <module>
    thumb_up_i = R.img('priconne/gadget/thumb-up-i.png').open().resize((16, 16), Image.LANCZOS)
  File "/root/HoshinoBot/hoshino/R.py", line 50, in open
    return Image.open(self.path)
  File "/usr/local/lib/python3.8/site-packages/PIL/Image.py", line 2904, in open
    fp = builtins.open(filename, "rb")
FileNotFoundError: [Errno 2] No such file or directory: './res/img/priconne/gadget/thumb-up-i.png'
[2021-01-22 21:01:56,180 nonebot] ERROR: Failed to import "hoshino.modules.groupmaster.chat", error: on_keyword() got multiple values for argument 'only_to_me'
[2021-01-22 21:01:56,180 nonebot] ERROR: on_keyword() got multiple values for argument 'only_to_me'
Traceback (most recent call last):
  File "/usr/local/lib/python3.8/site-packages/nonebot/plugin.py", line 274, in load_plugin
    module = importlib.import_module(module_path)
  File "/usr/local/lib/python3.8/importlib/__init__.py", line 127, in import_module
    return _bootstrap._gcd_import(name[level:], package, level)
  File "<frozen importlib._bootstrap>", line 1014, in _gcd_import
  File "<frozen importlib._bootstrap>", line 991, in _find_and_load
  File "<frozen importlib._bootstrap>", line 975, in _find_and_load_unlocked
  File "<frozen importlib._bootstrap>", line 671, in _load_unlocked
  File "<frozen importlib._bootstrap_external>", line 783, in exec_module
  File "<frozen importlib._bootstrap>", line 219, in _call_with_frames_removed
  File "/root/HoshinoBot/hoshino/modules/groupmaster/chat.py", line 59, in <module>
    @sv.on_keyword('ue','春田', only_to_me=True)
TypeError: on_keyword() got multiple values for argument 'only_to_me'
[2021-01-22 21:01:56,771 hoshino] ERROR: 缺少图片资源：./res/img/priconne/gadget/thumb-up-i.png
[2021-01-22 21:01:56,771 pcr-arena] ERROR: [Errno 2] No such file or directory: './res/img/priconne/gadget/thumb-up-i.png'
Traceback (most recent call last):
  File "/root/HoshinoBot/hoshino/modules/priconne/arena/__init__.py", line 31, in <module>
    thumb_up_i = R.img('priconne/gadget/thumb-up-i.png').open().resize((16, 16), Image.LANCZOS)
  File "/root/HoshinoBot/hoshino/R.py", line 50, in open
    return Image.open(self.path)
  File "/usr/local/lib/python3.8/site-packages/PIL/Image.py", line 2904, in open
    fp = builtins.open(filename, "rb")
FileNotFoundError: [Errno 2] No such file or directory: './res/img/priconne/gadget/thumb-up-i.png'
[2021-01-22 22:25:35,247 pcr-comic] ERROR: <class 'requests.exceptions.ReadTimeout'> occured when doing scheduled job update_seeker.
[2021-01-22 22:25:35,248 pcr-comic] ERROR: HTTPSConnectionPool(host='comic.priconne-redive.jp', port=443): Read timed out. (read timeout=10)
Traceback (most recent call last):
  File "/usr/local/lib/python3.8/site-packages/urllib3/connectionpool.py", line 382, in _make_request
    self._validate_conn(conn)
  File "/usr/local/lib/python3.8/site-packages/urllib3/connectionpool.py", line 1010, in _validate_conn
    conn.connect()
  File "/usr/local/lib/python3.8/site-packages/urllib3/connection.py", line 411, in connect
    self.sock = ssl_wrap_socket(
  File "/usr/local/lib/python3.8/site-packages/urllib3/util/ssl_.py", line 428, in ssl_wrap_socket
    ssl_sock = _ssl_wrap_socket_impl(
  File "/usr/local/lib/python3.8/site-packages/urllib3/util/ssl_.py", line 472, in _ssl_wrap_socket_impl
    return ssl_context.wrap_socket(sock, server_hostname=server_hostname)
  File "/usr/local/lib/python3.8/ssl.py", line 500, in wrap_socket
    return self.sslsocket_class._create(
  File "/usr/local/lib/python3.8/ssl.py", line 1040, in _create
    self.do_handshake()
  File "/usr/local/lib/python3.8/ssl.py", line 1309, in do_handshake
    self._sslobj.do_handshake()
socket.timeout: _ssl.c:1107: The handshake operation timed out

During handling of the above exception, another exception occurred:

Traceback (most recent call last):
  File "/usr/local/lib/python3.8/site-packages/requests/adapters.py", line 439, in send
    resp = conn.urlopen(
  File "/usr/local/lib/python3.8/site-packages/urllib3/connectionpool.py", line 755, in urlopen
    retries = retries.increment(
  File "/usr/local/lib/python3.8/site-packages/urllib3/util/retry.py", line 531, in increment
    raise six.reraise(type(error), error, _stacktrace)
  File "/usr/local/lib/python3.8/site-packages/urllib3/packages/six.py", line 735, in reraise
    raise value
  File "/usr/local/lib/python3.8/site-packages/urllib3/connectionpool.py", line 699, in urlopen
    httplib_response = self._make_request(
  File "/usr/local/lib/python3.8/site-packages/urllib3/connectionpool.py", line 385, in _make_request
    self._raise_timeout(err=e, url=url, timeout_value=conn.timeout)
  File "/usr/local/lib/python3.8/site-packages/urllib3/connectionpool.py", line 336, in _raise_timeout
    raise ReadTimeoutError(
urllib3.exceptions.ReadTimeoutError: HTTPSConnectionPool(host='comic.priconne-redive.jp', port=443): Read timed out. (read timeout=10)

During handling of the above exception, another exception occurred:

Traceback (most recent call last):
  File "/root/HoshinoBot/hoshino/service.py", line 325, in wrapper
    ret = await func()
  File "/root/HoshinoBot/hoshino/modules/priconne/comic.py", line 109, in update_seeker
    resp = await aiorequests.get(index_api, timeout=10)
  File "/root/HoshinoBot/hoshino/aiorequests.py", line 70, in get
    await run_sync_func(requests.get, url=url, params=params, **kwargs))
  File "/root/HoshinoBot/hoshino/aiorequests.py", line 10, in run_sync_func
    return await asyncio.get_event_loop().run_in_executor(
  File "/usr/local/lib/python3.8/concurrent/futures/thread.py", line 57, in run
    result = self.fn(*self.args, **self.kwargs)
  File "/usr/local/lib/python3.8/site-packages/requests/api.py", line 76, in get
    return request('get', url, params=params, **kwargs)
  File "/usr/local/lib/python3.8/site-packages/requests/api.py", line 61, in request
    return session.request(method=method, url=url, **kwargs)
  File "/usr/local/lib/python3.8/site-packages/requests/sessions.py", line 542, in request
    resp = self.send(prep, **send_kwargs)
  File "/usr/local/lib/python3.8/site-packages/requests/sessions.py", line 655, in send
    r = adapter.send(request, **kwargs)
  File "/usr/local/lib/python3.8/site-packages/requests/adapters.py", line 529, in send
    raise ReadTimeout(e, request=request)
requests.exceptions.ReadTimeout: HTTPSConnectionPool(host='comic.priconne-redive.jp', port=443): Read timed out. (read timeout=10)
[2021-01-23 17:35:52,352 pcr-comic] ERROR: <class 'requests.exceptions.ReadTimeout'> occured when doing scheduled job update_seeker.
[2021-01-23 17:35:52,353 pcr-comic] ERROR: HTTPSConnectionPool(host='comic.priconne-redive.jp', port=443): Read timed out. (read timeout=10)
Traceback (most recent call last):
  File "/usr/local/lib/python3.8/site-packages/urllib3/connectionpool.py", line 382, in _make_request
    self._validate_conn(conn)
  File "/usr/local/lib/python3.8/site-packages/urllib3/connectionpool.py", line 1010, in _validate_conn
    conn.connect()
  File "/usr/local/lib/python3.8/site-packages/urllib3/connection.py", line 411, in connect
    self.sock = ssl_wrap_socket(
  File "/usr/local/lib/python3.8/site-packages/urllib3/util/ssl_.py", line 428, in ssl_wrap_socket
    ssl_sock = _ssl_wrap_socket_impl(
  File "/usr/local/lib/python3.8/site-packages/urllib3/util/ssl_.py", line 472, in _ssl_wrap_socket_impl
    return ssl_context.wrap_socket(sock, server_hostname=server_hostname)
  File "/usr/local/lib/python3.8/ssl.py", line 500, in wrap_socket
    return self.sslsocket_class._create(
  File "/usr/local/lib/python3.8/ssl.py", line 1040, in _create
    self.do_handshake()
  File "/usr/local/lib/python3.8/ssl.py", line 1309, in do_handshake
    self._sslobj.do_handshake()
socket.timeout: _ssl.c:1107: The handshake operation timed out

During handling of the above exception, another exception occurred:

Traceback (most recent call last):
  File "/usr/local/lib/python3.8/site-packages/requests/adapters.py", line 439, in send
    resp = conn.urlopen(
  File "/usr/local/lib/python3.8/site-packages/urllib3/connectionpool.py", line 755, in urlopen
    retries = retries.increment(
  File "/usr/local/lib/python3.8/site-packages/urllib3/util/retry.py", line 531, in increment
    raise six.reraise(type(error), error, _stacktrace)
  File "/usr/local/lib/python3.8/site-packages/urllib3/packages/six.py", line 735, in reraise
    raise value
  File "/usr/local/lib/python3.8/site-packages/urllib3/connectionpool.py", line 699, in urlopen
    httplib_response = self._make_request(
  File "/usr/local/lib/python3.8/site-packages/urllib3/connectionpool.py", line 385, in _make_request
    self._raise_timeout(err=e, url=url, timeout_value=conn.timeout)
  File "/usr/local/lib/python3.8/site-packages/urllib3/connectionpool.py", line 336, in _raise_timeout
    raise ReadTimeoutError(
urllib3.exceptions.ReadTimeoutError: HTTPSConnectionPool(host='comic.priconne-redive.jp', port=443): Read timed out. (read timeout=10)

During handling of the above exception, another exception occurred:

Traceback (most recent call last):
  File "/root/HoshinoBot/hoshino/service.py", line 325, in wrapper
    ret = await func()
  File "/root/HoshinoBot/hoshino/modules/priconne/comic.py", line 109, in update_seeker
    resp = await aiorequests.get(index_api, timeout=10)
  File "/root/HoshinoBot/hoshino/aiorequests.py", line 70, in get
    await run_sync_func(requests.get, url=url, params=params, **kwargs))
  File "/root/HoshinoBot/hoshino/aiorequests.py", line 10, in run_sync_func
    return await asyncio.get_event_loop().run_in_executor(
  File "/usr/local/lib/python3.8/concurrent/futures/thread.py", line 57, in run
    result = self.fn(*self.args, **self.kwargs)
  File "/usr/local/lib/python3.8/site-packages/requests/api.py", line 76, in get
    return request('get', url, params=params, **kwargs)
  File "/usr/local/lib/python3.8/site-packages/requests/api.py", line 61, in request
    return session.request(method=method, url=url, **kwargs)
  File "/usr/local/lib/python3.8/site-packages/requests/sessions.py", line 542, in request
    resp = self.send(prep, **send_kwargs)
  File "/usr/local/lib/python3.8/site-packages/requests/sessions.py", line 655, in send
    r = adapter.send(request, **kwargs)
  File "/usr/local/lib/python3.8/site-packages/requests/adapters.py", line 529, in send
    raise ReadTimeout(e, request=request)
requests.exceptions.ReadTimeout: HTTPSConnectionPool(host='comic.priconne-redive.jp', port=443): Read timed out. (read timeout=10)
[2021-01-23 17:40:36,600 pcr-comic] ERROR: <class 'requests.exceptions.ReadTimeout'> occured when doing scheduled job update_seeker.
[2021-01-23 17:40:36,601 pcr-comic] ERROR: HTTPSConnectionPool(host='comic.priconne-redive.jp', port=443): Read timed out. (read timeout=10)
Traceback (most recent call last):
  File "/usr/local/lib/python3.8/site-packages/urllib3/connectionpool.py", line 445, in _make_request
    six.raise_from(e, None)
  File "<string>", line 3, in raise_from
  File "/usr/local/lib/python3.8/site-packages/urllib3/connectionpool.py", line 440, in _make_request
    httplib_response = conn.getresponse()
  File "/usr/local/lib/python3.8/http/client.py", line 1347, in getresponse
    response.begin()
  File "/usr/local/lib/python3.8/http/client.py", line 307, in begin
    version, status, reason = self._read_status()
  File "/usr/local/lib/python3.8/http/client.py", line 268, in _read_status
    line = str(self.fp.readline(_MAXLINE + 1), "iso-8859-1")
  File "/usr/local/lib/python3.8/socket.py", line 669, in readinto
    return self._sock.recv_into(b)
  File "/usr/local/lib/python3.8/ssl.py", line 1241, in recv_into
    return self.read(nbytes, buffer)
  File "/usr/local/lib/python3.8/ssl.py", line 1099, in read
    return self._sslobj.read(len, buffer)
socket.timeout: The read operation timed out

During handling of the above exception, another exception occurred:

Traceback (most recent call last):
  File "/usr/local/lib/python3.8/site-packages/requests/adapters.py", line 439, in send
    resp = conn.urlopen(
  File "/usr/local/lib/python3.8/site-packages/urllib3/connectionpool.py", line 755, in urlopen
    retries = retries.increment(
  File "/usr/local/lib/python3.8/site-packages/urllib3/util/retry.py", line 531, in increment
    raise six.reraise(type(error), error, _stacktrace)
  File "/usr/local/lib/python3.8/site-packages/urllib3/packages/six.py", line 735, in reraise
    raise value
  File "/usr/local/lib/python3.8/site-packages/urllib3/connectionpool.py", line 699, in urlopen
    httplib_response = self._make_request(
  File "/usr/local/lib/python3.8/site-packages/urllib3/connectionpool.py", line 447, in _make_request
    self._raise_timeout(err=e, url=url, timeout_value=read_timeout)
  File "/usr/local/lib/python3.8/site-packages/urllib3/connectionpool.py", line 336, in _raise_timeout
    raise ReadTimeoutError(
urllib3.exceptions.ReadTimeoutError: HTTPSConnectionPool(host='comic.priconne-redive.jp', port=443): Read timed out. (read timeout=10)

During handling of the above exception, another exception occurred:

Traceback (most recent call last):
  File "/root/HoshinoBot/hoshino/service.py", line 325, in wrapper
    ret = await func()
  File "/root/HoshinoBot/hoshino/modules/priconne/comic.py", line 109, in update_seeker
    resp = await aiorequests.get(index_api, timeout=10)
  File "/root/HoshinoBot/hoshino/aiorequests.py", line 70, in get
    await run_sync_func(requests.get, url=url, params=params, **kwargs))
  File "/root/HoshinoBot/hoshino/aiorequests.py", line 10, in run_sync_func
    return await asyncio.get_event_loop().run_in_executor(
  File "/usr/local/lib/python3.8/concurrent/futures/thread.py", line 57, in run
    result = self.fn(*self.args, **self.kwargs)
  File "/usr/local/lib/python3.8/site-packages/requests/api.py", line 76, in get
    return request('get', url, params=params, **kwargs)
  File "/usr/local/lib/python3.8/site-packages/requests/api.py", line 61, in request
    return session.request(method=method, url=url, **kwargs)
  File "/usr/local/lib/python3.8/site-packages/requests/sessions.py", line 542, in request
    resp = self.send(prep, **send_kwargs)
  File "/usr/local/lib/python3.8/site-packages/requests/sessions.py", line 655, in send
    r = adapter.send(request, **kwargs)
  File "/usr/local/lib/python3.8/site-packages/requests/adapters.py", line 529, in send
    raise ReadTimeout(e, request=request)
requests.exceptions.ReadTimeout: HTTPSConnectionPool(host='comic.priconne-redive.jp', port=443): Read timed out. (read timeout=10)
[2021-01-23 17:55:40,296 pcr-comic] ERROR: <class 'requests.exceptions.ReadTimeout'> occured when doing scheduled job update_seeker.
[2021-01-23 17:55:40,297 pcr-comic] ERROR: HTTPSConnectionPool(host='comic.priconne-redive.jp', port=443): Read timed out. (read timeout=10)
Traceback (most recent call last):
  File "/usr/local/lib/python3.8/site-packages/urllib3/connectionpool.py", line 382, in _make_request
    self._validate_conn(conn)
  File "/usr/local/lib/python3.8/site-packages/urllib3/connectionpool.py", line 1010, in _validate_conn
    conn.connect()
  File "/usr/local/lib/python3.8/site-packages/urllib3/connection.py", line 411, in connect
    self.sock = ssl_wrap_socket(
  File "/usr/local/lib/python3.8/site-packages/urllib3/util/ssl_.py", line 428, in ssl_wrap_socket
    ssl_sock = _ssl_wrap_socket_impl(
  File "/usr/local/lib/python3.8/site-packages/urllib3/util/ssl_.py", line 472, in _ssl_wrap_socket_impl
    return ssl_context.wrap_socket(sock, server_hostname=server_hostname)
  File "/usr/local/lib/python3.8/ssl.py", line 500, in wrap_socket
    return self.sslsocket_class._create(
  File "/usr/local/lib/python3.8/ssl.py", line 1040, in _create
    self.do_handshake()
  File "/usr/local/lib/python3.8/ssl.py", line 1309, in do_handshake
    self._sslobj.do_handshake()
socket.timeout: _ssl.c:1107: The handshake operation timed out

During handling of the above exception, another exception occurred:

Traceback (most recent call last):
  File "/usr/local/lib/python3.8/site-packages/requests/adapters.py", line 439, in send
    resp = conn.urlopen(
  File "/usr/local/lib/python3.8/site-packages/urllib3/connectionpool.py", line 755, in urlopen
    retries = retries.increment(
  File "/usr/local/lib/python3.8/site-packages/urllib3/util/retry.py", line 531, in increment
    raise six.reraise(type(error), error, _stacktrace)
  File "/usr/local/lib/python3.8/site-packages/urllib3/packages/six.py", line 735, in reraise
    raise value
  File "/usr/local/lib/python3.8/site-packages/urllib3/connectionpool.py", line 699, in urlopen
    httplib_response = self._make_request(
  File "/usr/local/lib/python3.8/site-packages/urllib3/connectionpool.py", line 385, in _make_request
    self._raise_timeout(err=e, url=url, timeout_value=conn.timeout)
  File "/usr/local/lib/python3.8/site-packages/urllib3/connectionpool.py", line 336, in _raise_timeout
    raise ReadTimeoutError(
urllib3.exceptions.ReadTimeoutError: HTTPSConnectionPool(host='comic.priconne-redive.jp', port=443): Read timed out. (read timeout=10)

During handling of the above exception, another exception occurred:

Traceback (most recent call last):
  File "/root/HoshinoBot/hoshino/service.py", line 325, in wrapper
    ret = await func()
  File "/root/HoshinoBot/hoshino/modules/priconne/comic.py", line 109, in update_seeker
    resp = await aiorequests.get(index_api, timeout=10)
  File "/root/HoshinoBot/hoshino/aiorequests.py", line 70, in get
    await run_sync_func(requests.get, url=url, params=params, **kwargs))
  File "/root/HoshinoBot/hoshino/aiorequests.py", line 10, in run_sync_func
    return await asyncio.get_event_loop().run_in_executor(
  File "/usr/local/lib/python3.8/concurrent/futures/thread.py", line 57, in run
    result = self.fn(*self.args, **self.kwargs)
  File "/usr/local/lib/python3.8/site-packages/requests/api.py", line 76, in get
    return request('get', url, params=params, **kwargs)
  File "/usr/local/lib/python3.8/site-packages/requests/api.py", line 61, in request
    return session.request(method=method, url=url, **kwargs)
  File "/usr/local/lib/python3.8/site-packages/requests/sessions.py", line 542, in request
    resp = self.send(prep, **send_kwargs)
  File "/usr/local/lib/python3.8/site-packages/requests/sessions.py", line 655, in send
    r = adapter.send(request, **kwargs)
  File "/usr/local/lib/python3.8/site-packages/requests/adapters.py", line 529, in send
    raise ReadTimeout(e, request=request)
requests.exceptions.ReadTimeout: HTTPSConnectionPool(host='comic.priconne-redive.jp', port=443): Read timed out. (read timeout=10)
[2021-01-23 18:05:38,344 pcr-comic] ERROR: <class 'requests.exceptions.ReadTimeout'> occured when doing scheduled job update_seeker.
[2021-01-23 18:05:38,345 pcr-comic] ERROR: HTTPSConnectionPool(host='comic.priconne-redive.jp', port=443): Read timed out. (read timeout=10)
Traceback (most recent call last):
  File "/usr/local/lib/python3.8/site-packages/urllib3/connectionpool.py", line 382, in _make_request
    self._validate_conn(conn)
  File "/usr/local/lib/python3.8/site-packages/urllib3/connectionpool.py", line 1010, in _validate_conn
    conn.connect()
  File "/usr/local/lib/python3.8/site-packages/urllib3/connection.py", line 411, in connect
    self.sock = ssl_wrap_socket(
  File "/usr/local/lib/python3.8/site-packages/urllib3/util/ssl_.py", line 428, in ssl_wrap_socket
    ssl_sock = _ssl_wrap_socket_impl(
  File "/usr/local/lib/python3.8/site-packages/urllib3/util/ssl_.py", line 472, in _ssl_wrap_socket_impl
    return ssl_context.wrap_socket(sock, server_hostname=server_hostname)
  File "/usr/local/lib/python3.8/ssl.py", line 500, in wrap_socket
    return self.sslsocket_class._create(
  File "/usr/local/lib/python3.8/ssl.py", line 1040, in _create
    self.do_handshake()
  File "/usr/local/lib/python3.8/ssl.py", line 1309, in do_handshake
    self._sslobj.do_handshake()
socket.timeout: _ssl.c:1107: The handshake operation timed out

During handling of the above exception, another exception occurred:

Traceback (most recent call last):
  File "/usr/local/lib/python3.8/site-packages/requests/adapters.py", line 439, in send
    resp = conn.urlopen(
  File "/usr/local/lib/python3.8/site-packages/urllib3/connectionpool.py", line 755, in urlopen
    retries = retries.increment(
  File "/usr/local/lib/python3.8/site-packages/urllib3/util/retry.py", line 531, in increment
    raise six.reraise(type(error), error, _stacktrace)
  File "/usr/local/lib/python3.8/site-packages/urllib3/packages/six.py", line 735, in reraise
    raise value
  File "/usr/local/lib/python3.8/site-packages/urllib3/connectionpool.py", line 699, in urlopen
    httplib_response = self._make_request(
  File "/usr/local/lib/python3.8/site-packages/urllib3/connectionpool.py", line 385, in _make_request
    self._raise_timeout(err=e, url=url, timeout_value=conn.timeout)
  File "/usr/local/lib/python3.8/site-packages/urllib3/connectionpool.py", line 336, in _raise_timeout
    raise ReadTimeoutError(
urllib3.exceptions.ReadTimeoutError: HTTPSConnectionPool(host='comic.priconne-redive.jp', port=443): Read timed out. (read timeout=10)

During handling of the above exception, another exception occurred:

Traceback (most recent call last):
  File "/root/HoshinoBot/hoshino/service.py", line 325, in wrapper
    ret = await func()
  File "/root/HoshinoBot/hoshino/modules/priconne/comic.py", line 109, in update_seeker
    resp = await aiorequests.get(index_api, timeout=10)
  File "/root/HoshinoBot/hoshino/aiorequests.py", line 70, in get
    await run_sync_func(requests.get, url=url, params=params, **kwargs))
  File "/root/HoshinoBot/hoshino/aiorequests.py", line 10, in run_sync_func
    return await asyncio.get_event_loop().run_in_executor(
  File "/usr/local/lib/python3.8/concurrent/futures/thread.py", line 57, in run
    result = self.fn(*self.args, **self.kwargs)
  File "/usr/local/lib/python3.8/site-packages/requests/api.py", line 76, in get
    return request('get', url, params=params, **kwargs)
  File "/usr/local/lib/python3.8/site-packages/requests/api.py", line 61, in request
    return session.request(method=method, url=url, **kwargs)
  File "/usr/local/lib/python3.8/site-packages/requests/sessions.py", line 542, in request
    resp = self.send(prep, **send_kwargs)
  File "/usr/local/lib/python3.8/site-packages/requests/sessions.py", line 655, in send
    r = adapter.send(request, **kwargs)
  File "/usr/local/lib/python3.8/site-packages/requests/adapters.py", line 529, in send
    raise ReadTimeout(e, request=request)
requests.exceptions.ReadTimeout: HTTPSConnectionPool(host='comic.priconne-redive.jp', port=443): Read timed out. (read timeout=10)
[2021-01-23 19:30:39,456 pcr-comic] ERROR: <class 'requests.exceptions.ReadTimeout'> occured when doing scheduled job update_seeker.
[2021-01-23 19:30:39,457 pcr-comic] ERROR: HTTPSConnectionPool(host='comic.priconne-redive.jp', port=443): Read timed out. (read timeout=10)
Traceback (most recent call last):
  File "/usr/local/lib/python3.8/site-packages/urllib3/connectionpool.py", line 382, in _make_request
    self._validate_conn(conn)
  File "/usr/local/lib/python3.8/site-packages/urllib3/connectionpool.py", line 1010, in _validate_conn
    conn.connect()
  File "/usr/local/lib/python3.8/site-packages/urllib3/connection.py", line 411, in connect
    self.sock = ssl_wrap_socket(
  File "/usr/local/lib/python3.8/site-packages/urllib3/util/ssl_.py", line 428, in ssl_wrap_socket
    ssl_sock = _ssl_wrap_socket_impl(
  File "/usr/local/lib/python3.8/site-packages/urllib3/util/ssl_.py", line 472, in _ssl_wrap_socket_impl
    return ssl_context.wrap_socket(sock, server_hostname=server_hostname)
  File "/usr/local/lib/python3.8/ssl.py", line 500, in wrap_socket
    return self.sslsocket_class._create(
  File "/usr/local/lib/python3.8/ssl.py", line 1040, in _create
    self.do_handshake()
  File "/usr/local/lib/python3.8/ssl.py", line 1309, in do_handshake
    self._sslobj.do_handshake()
socket.timeout: _ssl.c:1107: The handshake operation timed out

During handling of the above exception, another exception occurred:

Traceback (most recent call last):
  File "/usr/local/lib/python3.8/site-packages/requests/adapters.py", line 439, in send
    resp = conn.urlopen(
  File "/usr/local/lib/python3.8/site-packages/urllib3/connectionpool.py", line 755, in urlopen
    retries = retries.increment(
  File "/usr/local/lib/python3.8/site-packages/urllib3/util/retry.py", line 531, in increment
    raise six.reraise(type(error), error, _stacktrace)
  File "/usr/local/lib/python3.8/site-packages/urllib3/packages/six.py", line 735, in reraise
    raise value
  File "/usr/local/lib/python3.8/site-packages/urllib3/connectionpool.py", line 699, in urlopen
    httplib_response = self._make_request(
  File "/usr/local/lib/python3.8/site-packages/urllib3/connectionpool.py", line 385, in _make_request
    self._raise_timeout(err=e, url=url, timeout_value=conn.timeout)
  File "/usr/local/lib/python3.8/site-packages/urllib3/connectionpool.py", line 336, in _raise_timeout
    raise ReadTimeoutError(
urllib3.exceptions.ReadTimeoutError: HTTPSConnectionPool(host='comic.priconne-redive.jp', port=443): Read timed out. (read timeout=10)

During handling of the above exception, another exception occurred:

Traceback (most recent call last):
  File "/root/HoshinoBot/hoshino/service.py", line 325, in wrapper
    ret = await func()
  File "/root/HoshinoBot/hoshino/modules/priconne/comic.py", line 109, in update_seeker
    resp = await aiorequests.get(index_api, timeout=10)
  File "/root/HoshinoBot/hoshino/aiorequests.py", line 70, in get
    await run_sync_func(requests.get, url=url, params=params, **kwargs))
  File "/root/HoshinoBot/hoshino/aiorequests.py", line 10, in run_sync_func
    return await asyncio.get_event_loop().run_in_executor(
  File "/usr/local/lib/python3.8/concurrent/futures/thread.py", line 57, in run
    result = self.fn(*self.args, **self.kwargs)
  File "/usr/local/lib/python3.8/site-packages/requests/api.py", line 76, in get
    return request('get', url, params=params, **kwargs)
  File "/usr/local/lib/python3.8/site-packages/requests/api.py", line 61, in request
    return session.request(method=method, url=url, **kwargs)
  File "/usr/local/lib/python3.8/site-packages/requests/sessions.py", line 542, in request
    resp = self.send(prep, **send_kwargs)
  File "/usr/local/lib/python3.8/site-packages/requests/sessions.py", line 655, in send
    r = adapter.send(request, **kwargs)
  File "/usr/local/lib/python3.8/site-packages/requests/adapters.py", line 529, in send
    raise ReadTimeout(e, request=request)
requests.exceptions.ReadTimeout: HTTPSConnectionPool(host='comic.priconne-redive.jp', port=443): Read timed out. (read timeout=10)
[2021-01-23 20:25:39,412 pcr-comic] ERROR: <class 'requests.exceptions.ReadTimeout'> occured when doing scheduled job update_seeker.
[2021-01-23 20:25:39,415 pcr-comic] ERROR: HTTPSConnectionPool(host='comic.priconne-redive.jp', port=443): Read timed out. (read timeout=10)
Traceback (most recent call last):
  File "/usr/local/lib/python3.8/site-packages/urllib3/connectionpool.py", line 445, in _make_request
    six.raise_from(e, None)
  File "<string>", line 3, in raise_from
  File "/usr/local/lib/python3.8/site-packages/urllib3/connectionpool.py", line 440, in _make_request
    httplib_response = conn.getresponse()
  File "/usr/local/lib/python3.8/http/client.py", line 1347, in getresponse
    response.begin()
  File "/usr/local/lib/python3.8/http/client.py", line 307, in begin
    version, status, reason = self._read_status()
  File "/usr/local/lib/python3.8/http/client.py", line 268, in _read_status
    line = str(self.fp.readline(_MAXLINE + 1), "iso-8859-1")
  File "/usr/local/lib/python3.8/socket.py", line 669, in readinto
    return self._sock.recv_into(b)
  File "/usr/local/lib/python3.8/ssl.py", line 1241, in recv_into
    return self.read(nbytes, buffer)
  File "/usr/local/lib/python3.8/ssl.py", line 1099, in read
    return self._sslobj.read(len, buffer)
socket.timeout: The read operation timed out

During handling of the above exception, another exception occurred:

Traceback (most recent call last):
  File "/usr/local/lib/python3.8/site-packages/requests/adapters.py", line 439, in send
    resp = conn.urlopen(
  File "/usr/local/lib/python3.8/site-packages/urllib3/connectionpool.py", line 755, in urlopen
    retries = retries.increment(
  File "/usr/local/lib/python3.8/site-packages/urllib3/util/retry.py", line 531, in increment
    raise six.reraise(type(error), error, _stacktrace)
  File "/usr/local/lib/python3.8/site-packages/urllib3/packages/six.py", line 735, in reraise
    raise value
  File "/usr/local/lib/python3.8/site-packages/urllib3/connectionpool.py", line 699, in urlopen
    httplib_response = self._make_request(
  File "/usr/local/lib/python3.8/site-packages/urllib3/connectionpool.py", line 447, in _make_request
    self._raise_timeout(err=e, url=url, timeout_value=read_timeout)
  File "/usr/local/lib/python3.8/site-packages/urllib3/connectionpool.py", line 336, in _raise_timeout
    raise ReadTimeoutError(
urllib3.exceptions.ReadTimeoutError: HTTPSConnectionPool(host='comic.priconne-redive.jp', port=443): Read timed out. (read timeout=10)

During handling of the above exception, another exception occurred:

Traceback (most recent call last):
  File "/root/HoshinoBot/hoshino/service.py", line 325, in wrapper
    ret = await func()
  File "/root/HoshinoBot/hoshino/modules/priconne/comic.py", line 109, in update_seeker
    resp = await aiorequests.get(index_api, timeout=10)
  File "/root/HoshinoBot/hoshino/aiorequests.py", line 70, in get
    await run_sync_func(requests.get, url=url, params=params, **kwargs))
  File "/root/HoshinoBot/hoshino/aiorequests.py", line 10, in run_sync_func
    return await asyncio.get_event_loop().run_in_executor(
  File "/usr/local/lib/python3.8/concurrent/futures/thread.py", line 57, in run
    result = self.fn(*self.args, **self.kwargs)
  File "/usr/local/lib/python3.8/site-packages/requests/api.py", line 76, in get
    return request('get', url, params=params, **kwargs)
  File "/usr/local/lib/python3.8/site-packages/requests/api.py", line 61, in request
    return session.request(method=method, url=url, **kwargs)
  File "/usr/local/lib/python3.8/site-packages/requests/sessions.py", line 542, in request
    resp = self.send(prep, **send_kwargs)
  File "/usr/local/lib/python3.8/site-packages/requests/sessions.py", line 655, in send
    r = adapter.send(request, **kwargs)
  File "/usr/local/lib/python3.8/site-packages/requests/adapters.py", line 529, in send
    raise ReadTimeout(e, request=request)
requests.exceptions.ReadTimeout: HTTPSConnectionPool(host='comic.priconne-redive.jp', port=443): Read timed out. (read timeout=10)
[2021-01-23 20:30:35,341 pcr-comic] ERROR: <class 'requests.exceptions.ReadTimeout'> occured when doing scheduled job update_seeker.
[2021-01-23 20:30:35,341 pcr-comic] ERROR: HTTPSConnectionPool(host='comic.priconne-redive.jp', port=443): Read timed out. (read timeout=10)
Traceback (most recent call last):
  File "/usr/local/lib/python3.8/site-packages/urllib3/connectionpool.py", line 382, in _make_request
    self._validate_conn(conn)
  File "/usr/local/lib/python3.8/site-packages/urllib3/connectionpool.py", line 1010, in _validate_conn
    conn.connect()
  File "/usr/local/lib/python3.8/site-packages/urllib3/connection.py", line 411, in connect
    self.sock = ssl_wrap_socket(
  File "/usr/local/lib/python3.8/site-packages/urllib3/util/ssl_.py", line 428, in ssl_wrap_socket
    ssl_sock = _ssl_wrap_socket_impl(
  File "/usr/local/lib/python3.8/site-packages/urllib3/util/ssl_.py", line 472, in _ssl_wrap_socket_impl
    return ssl_context.wrap_socket(sock, server_hostname=server_hostname)
  File "/usr/local/lib/python3.8/ssl.py", line 500, in wrap_socket
    return self.sslsocket_class._create(
  File "/usr/local/lib/python3.8/ssl.py", line 1040, in _create
    self.do_handshake()
  File "/usr/local/lib/python3.8/ssl.py", line 1309, in do_handshake
    self._sslobj.do_handshake()
socket.timeout: _ssl.c:1107: The handshake operation timed out

During handling of the above exception, another exception occurred:

Traceback (most recent call last):
  File "/usr/local/lib/python3.8/site-packages/requests/adapters.py", line 439, in send
    resp = conn.urlopen(
  File "/usr/local/lib/python3.8/site-packages/urllib3/connectionpool.py", line 755, in urlopen
    retries = retries.increment(
  File "/usr/local/lib/python3.8/site-packages/urllib3/util/retry.py", line 531, in increment
    raise six.reraise(type(error), error, _stacktrace)
  File "/usr/local/lib/python3.8/site-packages/urllib3/packages/six.py", line 735, in reraise
    raise value
  File "/usr/local/lib/python3.8/site-packages/urllib3/connectionpool.py", line 699, in urlopen
    httplib_response = self._make_request(
  File "/usr/local/lib/python3.8/site-packages/urllib3/connectionpool.py", line 385, in _make_request
    self._raise_timeout(err=e, url=url, timeout_value=conn.timeout)
  File "/usr/local/lib/python3.8/site-packages/urllib3/connectionpool.py", line 336, in _raise_timeout
    raise ReadTimeoutError(
urllib3.exceptions.ReadTimeoutError: HTTPSConnectionPool(host='comic.priconne-redive.jp', port=443): Read timed out. (read timeout=10)

During handling of the above exception, another exception occurred:

Traceback (most recent call last):
  File "/root/HoshinoBot/hoshino/service.py", line 325, in wrapper
    ret = await func()
  File "/root/HoshinoBot/hoshino/modules/priconne/comic.py", line 109, in update_seeker
    resp = await aiorequests.get(index_api, timeout=10)
  File "/root/HoshinoBot/hoshino/aiorequests.py", line 70, in get
    await run_sync_func(requests.get, url=url, params=params, **kwargs))
  File "/root/HoshinoBot/hoshino/aiorequests.py", line 10, in run_sync_func
    return await asyncio.get_event_loop().run_in_executor(
  File "/usr/local/lib/python3.8/concurrent/futures/thread.py", line 57, in run
    result = self.fn(*self.args, **self.kwargs)
  File "/usr/local/lib/python3.8/site-packages/requests/api.py", line 76, in get
    return request('get', url, params=params, **kwargs)
  File "/usr/local/lib/python3.8/site-packages/requests/api.py", line 61, in request
    return session.request(method=method, url=url, **kwargs)
  File "/usr/local/lib/python3.8/site-packages/requests/sessions.py", line 542, in request
    resp = self.send(prep, **send_kwargs)
  File "/usr/local/lib/python3.8/site-packages/requests/sessions.py", line 655, in send
    r = adapter.send(request, **kwargs)
  File "/usr/local/lib/python3.8/site-packages/requests/adapters.py", line 529, in send
    raise ReadTimeout(e, request=request)
requests.exceptions.ReadTimeout: HTTPSConnectionPool(host='comic.priconne-redive.jp', port=443): Read timed out. (read timeout=10)
[2021-01-23 21:10:36,284 pcr-comic] ERROR: <class 'requests.exceptions.ReadTimeout'> occured when doing scheduled job update_seeker.
[2021-01-23 21:10:36,285 pcr-comic] ERROR: HTTPSConnectionPool(host='comic.priconne-redive.jp', port=443): Read timed out. (read timeout=10)
Traceback (most recent call last):
  File "/usr/local/lib/python3.8/site-packages/urllib3/connectionpool.py", line 382, in _make_request
    self._validate_conn(conn)
  File "/usr/local/lib/python3.8/site-packages/urllib3/connectionpool.py", line 1010, in _validate_conn
    conn.connect()
  File "/usr/local/lib/python3.8/site-packages/urllib3/connection.py", line 411, in connect
    self.sock = ssl_wrap_socket(
  File "/usr/local/lib/python3.8/site-packages/urllib3/util/ssl_.py", line 428, in ssl_wrap_socket
    ssl_sock = _ssl_wrap_socket_impl(
  File "/usr/local/lib/python3.8/site-packages/urllib3/util/ssl_.py", line 472, in _ssl_wrap_socket_impl
    return ssl_context.wrap_socket(sock, server_hostname=server_hostname)
  File "/usr/local/lib/python3.8/ssl.py", line 500, in wrap_socket
    return self.sslsocket_class._create(
  File "/usr/local/lib/python3.8/ssl.py", line 1040, in _create
    self.do_handshake()
  File "/usr/local/lib/python3.8/ssl.py", line 1309, in do_handshake
    self._sslobj.do_handshake()
socket.timeout: _ssl.c:1107: The handshake operation timed out

During handling of the above exception, another exception occurred:

Traceback (most recent call last):
  File "/usr/local/lib/python3.8/site-packages/requests/adapters.py", line 439, in send
    resp = conn.urlopen(
  File "/usr/local/lib/python3.8/site-packages/urllib3/connectionpool.py", line 755, in urlopen
    retries = retries.increment(
  File "/usr/local/lib/python3.8/site-packages/urllib3/util/retry.py", line 531, in increment
    raise six.reraise(type(error), error, _stacktrace)
  File "/usr/local/lib/python3.8/site-packages/urllib3/packages/six.py", line 735, in reraise
    raise value
  File "/usr/local/lib/python3.8/site-packages/urllib3/connectionpool.py", line 699, in urlopen
    httplib_response = self._make_request(
  File "/usr/local/lib/python3.8/site-packages/urllib3/connectionpool.py", line 385, in _make_request
    self._raise_timeout(err=e, url=url, timeout_value=conn.timeout)
  File "/usr/local/lib/python3.8/site-packages/urllib3/connectionpool.py", line 336, in _raise_timeout
    raise ReadTimeoutError(
urllib3.exceptions.ReadTimeoutError: HTTPSConnectionPool(host='comic.priconne-redive.jp', port=443): Read timed out. (read timeout=10)

During handling of the above exception, another exception occurred:

Traceback (most recent call last):
  File "/root/HoshinoBot/hoshino/service.py", line 325, in wrapper
    ret = await func()
  File "/root/HoshinoBot/hoshino/modules/priconne/comic.py", line 109, in update_seeker
    resp = await aiorequests.get(index_api, timeout=10)
  File "/root/HoshinoBot/hoshino/aiorequests.py", line 70, in get
    await run_sync_func(requests.get, url=url, params=params, **kwargs))
  File "/root/HoshinoBot/hoshino/aiorequests.py", line 10, in run_sync_func
    return await asyncio.get_event_loop().run_in_executor(
  File "/usr/local/lib/python3.8/concurrent/futures/thread.py", line 57, in run
    result = self.fn(*self.args, **self.kwargs)
  File "/usr/local/lib/python3.8/site-packages/requests/api.py", line 76, in get
    return request('get', url, params=params, **kwargs)
  File "/usr/local/lib/python3.8/site-packages/requests/api.py", line 61, in request
    return session.request(method=method, url=url, **kwargs)
  File "/usr/local/lib/python3.8/site-packages/requests/sessions.py", line 542, in request
    resp = self.send(prep, **send_kwargs)
  File "/usr/local/lib/python3.8/site-packages/requests/sessions.py", line 655, in send
    r = adapter.send(request, **kwargs)
  File "/usr/local/lib/python3.8/site-packages/requests/adapters.py", line 529, in send
    raise ReadTimeout(e, request=request)
requests.exceptions.ReadTimeout: HTTPSConnectionPool(host='comic.priconne-redive.jp', port=443): Read timed out. (read timeout=10)
[2021-01-24 03:30:33,522 nonebot] ERROR: Failed to import "hoshino.modules.groupmaster.chat", error: on_keyword() got multiple values for argument 'only_to_me'
[2021-01-24 03:30:33,522 nonebot] ERROR: on_keyword() got multiple values for argument 'only_to_me'
Traceback (most recent call last):
  File "/usr/local/lib/python3.8/site-packages/nonebot/plugin.py", line 274, in load_plugin
    module = importlib.import_module(module_path)
  File "/usr/local/lib/python3.8/importlib/__init__.py", line 127, in import_module
    return _bootstrap._gcd_import(name[level:], package, level)
  File "<frozen importlib._bootstrap>", line 1014, in _gcd_import
  File "<frozen importlib._bootstrap>", line 991, in _find_and_load
  File "<frozen importlib._bootstrap>", line 975, in _find_and_load_unlocked
  File "<frozen importlib._bootstrap>", line 671, in _load_unlocked
  File "<frozen importlib._bootstrap_external>", line 783, in exec_module
  File "<frozen importlib._bootstrap>", line 219, in _call_with_frames_removed
  File "/root/HoshinoBot/hoshino/modules/groupmaster/chat.py", line 59, in <module>
    @sv.on_keyword('ue','春田', only_to_me=True)
TypeError: on_keyword() got multiple values for argument 'only_to_me'
[2021-01-24 03:30:33,780 hoshino] ERROR: 缺少图片资源：./res/img/priconne/gadget/thumb-up-i.png
[2021-01-24 03:30:33,780 pcr-arena] ERROR: [Errno 2] No such file or directory: './res/img/priconne/gadget/thumb-up-i.png'
Traceback (most recent call last):
  File "/root/HoshinoBot/hoshino/modules/priconne/arena/__init__.py", line 31, in <module>
    thumb_up_i = R.img('priconne/gadget/thumb-up-i.png').open().resize((16, 16), Image.LANCZOS)
  File "/root/HoshinoBot/hoshino/R.py", line 50, in open
    return Image.open(self.path)
  File "/usr/local/lib/python3.8/site-packages/PIL/Image.py", line 2904, in open
    fp = builtins.open(filename, "rb")
FileNotFoundError: [Errno 2] No such file or directory: './res/img/priconne/gadget/thumb-up-i.png'
[2021-01-24 03:43:15,846 hoshino] ERROR: 缺少图片资源：./res/img/priconne/gadget/thumb-up-i.png
[2021-01-24 03:43:15,847 pcr-arena] ERROR: [Errno 2] No such file or directory: './res/img/priconne/gadget/thumb-up-i.png'
Traceback (most recent call last):
  File "/root/HoshinoBot/hoshino/modules/priconne/arena/__init__.py", line 31, in <module>
    thumb_up_i = R.img('priconne/gadget/thumb-up-i.png').open().resize((16, 16), Image.LANCZOS)
  File "/root/HoshinoBot/hoshino/R.py", line 50, in open
    return Image.open(self.path)
  File "/usr/local/lib/python3.8/site-packages/PIL/Image.py", line 2904, in open
    fp = builtins.open(filename, "rb")
FileNotFoundError: [Errno 2] No such file or directory: './res/img/priconne/gadget/thumb-up-i.png'
[2021-01-24 03:43:16,574 nonebot] ERROR: Failed to import "hoshino.modules.groupmaster.chat", error: on_keyword() got multiple values for argument 'only_to_me'
[2021-01-24 03:43:16,576 nonebot] ERROR: on_keyword() got multiple values for argument 'only_to_me'
Traceback (most recent call last):
  File "/usr/local/lib/python3.8/site-packages/nonebot/plugin.py", line 274, in load_plugin
    module = importlib.import_module(module_path)
  File "/usr/local/lib/python3.8/importlib/__init__.py", line 127, in import_module
    return _bootstrap._gcd_import(name[level:], package, level)
  File "<frozen importlib._bootstrap>", line 1014, in _gcd_import
  File "<frozen importlib._bootstrap>", line 991, in _find_and_load
  File "<frozen importlib._bootstrap>", line 975, in _find_and_load_unlocked
  File "<frozen importlib._bootstrap>", line 671, in _load_unlocked
  File "<frozen importlib._bootstrap_external>", line 783, in exec_module
  File "<frozen importlib._bootstrap>", line 219, in _call_with_frames_removed
  File "/root/HoshinoBot/hoshino/modules/groupmaster/chat.py", line 59, in <module>
    @sv.on_keyword('ue','春田', only_to_me=True)
TypeError: on_keyword() got multiple values for argument 'only_to_me'
[2021-01-24 03:44:22,909 hoshino] CRITICAL: Self: 1142643359, Message 1219369690 from 123337671: cnm
[2021-01-25 00:13:27,536 setu_mix] ERROR: <class 'KeyError'> occured when doing scheduled job job.
[2021-01-25 00:13:27,536 setu_mix] ERROR: 'illust'
Traceback (most recent call last):
  File "/root/HoshinoBot/hoshino/service.py", line 325, in wrapper
    ret = await func()
  File "/root/HoshinoBot/hoshino/modules/setu_mix/__init__.py", line 232, in job
    await fetch_process()
  File "/root/HoshinoBot/hoshino/modules/setu_mix/base.py", line 119, in fetch_process
    await task
  File "/usr/local/lib/python3.8/asyncio/tasks.py", line 616, in _wait_for_one
    return f.result()  # May raise f.exception().
  File "/root/HoshinoBot/hoshino/modules/setu_mix/acggov.py", line 442, in acggov_fetch_process
    await acggov_get_ranking_setu(i)
  File "/root/HoshinoBot/hoshino/modules/setu_mix/acggov.py", line 406, in acggov_get_ranking_setu
    image = await query_ranking_setu(number)
  File "/root/HoshinoBot/hoshino/modules/setu_mix/acggov.py", line 204, in query_ranking_setu
    page_count = data['illust']['page_count']
KeyError: 'illust'
[2021-01-25 00:43:28,812 setu_mix] ERROR: <class 'KeyError'> occured when doing scheduled job job.
[2021-01-25 00:43:28,812 setu_mix] ERROR: 'illust'
Traceback (most recent call last):
  File "/root/HoshinoBot/hoshino/service.py", line 325, in wrapper
    ret = await func()
  File "/root/HoshinoBot/hoshino/modules/setu_mix/__init__.py", line 232, in job
    await fetch_process()
  File "/root/HoshinoBot/hoshino/modules/setu_mix/base.py", line 119, in fetch_process
    await task
  File "/usr/local/lib/python3.8/asyncio/tasks.py", line 616, in _wait_for_one
    return f.result()  # May raise f.exception().
  File "/root/HoshinoBot/hoshino/modules/setu_mix/acggov.py", line 442, in acggov_fetch_process
    await acggov_get_ranking_setu(i)
  File "/root/HoshinoBot/hoshino/modules/setu_mix/acggov.py", line 406, in acggov_get_ranking_setu
    image = await query_ranking_setu(number)
  File "/root/HoshinoBot/hoshino/modules/setu_mix/acggov.py", line 204, in query_ranking_setu
    page_count = data['illust']['page_count']
KeyError: 'illust'
[2021-01-25 01:13:26,821 setu_mix] ERROR: <class 'KeyError'> occured when doing scheduled job job.
[2021-01-25 01:13:26,827 setu_mix] ERROR: 'illust'
Traceback (most recent call last):
  File "/root/HoshinoBot/hoshino/service.py", line 325, in wrapper
    ret = await func()
  File "/root/HoshinoBot/hoshino/modules/setu_mix/__init__.py", line 232, in job
    await fetch_process()
  File "/root/HoshinoBot/hoshino/modules/setu_mix/base.py", line 119, in fetch_process
    await task
  File "/usr/local/lib/python3.8/asyncio/tasks.py", line 616, in _wait_for_one
    return f.result()  # May raise f.exception().
  File "/root/HoshinoBot/hoshino/modules/setu_mix/acggov.py", line 442, in acggov_fetch_process
    await acggov_get_ranking_setu(i)
  File "/root/HoshinoBot/hoshino/modules/setu_mix/acggov.py", line 406, in acggov_get_ranking_setu
    image = await query_ranking_setu(number)
  File "/root/HoshinoBot/hoshino/modules/setu_mix/acggov.py", line 204, in query_ranking_setu
    page_count = data['illust']['page_count']
KeyError: 'illust'
[2021-01-25 01:43:25,761 setu_mix] ERROR: <class 'KeyError'> occured when doing scheduled job job.
[2021-01-25 01:43:25,761 setu_mix] ERROR: 'illust'
Traceback (most recent call last):
  File "/root/HoshinoBot/hoshino/service.py", line 325, in wrapper
    ret = await func()
  File "/root/HoshinoBot/hoshino/modules/setu_mix/__init__.py", line 232, in job
    await fetch_process()
  File "/root/HoshinoBot/hoshino/modules/setu_mix/base.py", line 119, in fetch_process
    await task
  File "/usr/local/lib/python3.8/asyncio/tasks.py", line 616, in _wait_for_one
    return f.result()  # May raise f.exception().
  File "/root/HoshinoBot/hoshino/modules/setu_mix/acggov.py", line 442, in acggov_fetch_process
    await acggov_get_ranking_setu(i)
  File "/root/HoshinoBot/hoshino/modules/setu_mix/acggov.py", line 406, in acggov_get_ranking_setu
    image = await query_ranking_setu(number)
  File "/root/HoshinoBot/hoshino/modules/setu_mix/acggov.py", line 204, in query_ranking_setu
    page_count = data['illust']['page_count']
KeyError: 'illust'
[2021-01-25 02:13:25,507 setu_mix] ERROR: <class 'KeyError'> occured when doing scheduled job job.
[2021-01-25 02:13:25,508 setu_mix] ERROR: 'illust'
Traceback (most recent call last):
  File "/root/HoshinoBot/hoshino/service.py", line 325, in wrapper
    ret = await func()
  File "/root/HoshinoBot/hoshino/modules/setu_mix/__init__.py", line 232, in job
    await fetch_process()
  File "/root/HoshinoBot/hoshino/modules/setu_mix/base.py", line 119, in fetch_process
    await task
  File "/usr/local/lib/python3.8/asyncio/tasks.py", line 616, in _wait_for_one
    return f.result()  # May raise f.exception().
  File "/root/HoshinoBot/hoshino/modules/setu_mix/acggov.py", line 442, in acggov_fetch_process
    await acggov_get_ranking_setu(i)
  File "/root/HoshinoBot/hoshino/modules/setu_mix/acggov.py", line 406, in acggov_get_ranking_setu
    image = await query_ranking_setu(number)
  File "/root/HoshinoBot/hoshino/modules/setu_mix/acggov.py", line 204, in query_ranking_setu
    page_count = data['illust']['page_count']
KeyError: 'illust'
[2021-01-25 02:43:25,405 setu_mix] ERROR: <class 'KeyError'> occured when doing scheduled job job.
[2021-01-25 02:43:25,405 setu_mix] ERROR: 'illust'
Traceback (most recent call last):
  File "/root/HoshinoBot/hoshino/service.py", line 325, in wrapper
    ret = await func()
  File "/root/HoshinoBot/hoshino/modules/setu_mix/__init__.py", line 232, in job
    await fetch_process()
  File "/root/HoshinoBot/hoshino/modules/setu_mix/base.py", line 119, in fetch_process
    await task
  File "/usr/local/lib/python3.8/asyncio/tasks.py", line 616, in _wait_for_one
    return f.result()  # May raise f.exception().
  File "/root/HoshinoBot/hoshino/modules/setu_mix/acggov.py", line 442, in acggov_fetch_process
    await acggov_get_ranking_setu(i)
  File "/root/HoshinoBot/hoshino/modules/setu_mix/acggov.py", line 406, in acggov_get_ranking_setu
    image = await query_ranking_setu(number)
  File "/root/HoshinoBot/hoshino/modules/setu_mix/acggov.py", line 204, in query_ranking_setu
    page_count = data['illust']['page_count']
KeyError: 'illust'
